Workbook

Sheet Monthly (2024-2025)
B2: Kian Hoe Plantations Berhad (KHPB)
B3: MASS BALANCE (MB) WORKSHEET
B4: Year: 24/25
B5: Month | C5: Incoming POME to Digester (m3) | F5: Biogas Generated (m3) | I5: Biogas Supplied to Scrubber (m3) | L5: Biogas Supplied to Gas Engine (m3) | O5: Biogas Supplied to Biomethane Plant (m3) | R5: Volume CH4 in Raw Biogas (m3) | U5: Biomethane Generated (m3) | X5: Biomethane Supplied to Grid (m3) | AA5: Biomethane Supplied to Grid (MMBtu)
C10: ISCC | D10: Non-Certified | E10: TOTAL | F10: ISCC | G10: Non-Certified | H10: TOTAL | I10: ISCC | J10: Non-Certified | K10: TOTAL | L10: ISCC | M10: Non-Certified | N10: TOTAL | O10: ISCC | P10: Non-Certified | Q10: TOTAL | R10: ISCC | S10: Non-Certified | T10: TOTAL | U10: ISCC | V10: Non-Certified | W10: TOTAL | X10: ISCC | Y10: Non-Certified | Z10: TOTAL | AA10: ISCC | AB10: Non-Certified | AC10: TOTAL
B11: January | C11: 0 | D11: 0 | E11: =SUM(C11:D11) -> 0 | F11: 0 | G11: 0 | H11: =SUM(F11:G11) -> 0 | I11: 0 | J11: 0 | K11: =SUM(I11:J11) -> 0 | L11: 0 | M11: 0 | N11: =SUM(L11:M11) -> 0 | O11: 0 | P11: 0 | Q11: =SUM(O11:P11) -> 0 | R11: 0 | S11: 0 | T11: =R11+S11 -> 0 | U11: 0 | V11: 0 | W11: =U11+V11 -> 0 | X11: 0 | Y11: 0 | Z11: =X11+Y11 -> 0 | AA11: 0 | AB11: 0 | AC11: =AA11+AB11 -> 0
B12: February | C12: 0 | D12: 0 | E12: =SUM(C12:D12) -> 0 | F12: 0 | G12: 0 | H12: =SUM(F12:G12) -> 0 | I12: 0 | J12: 0 | K12: =SUM(I12:J12) -> 0 | L12: 0 | M12: 0 | N12: =SUM(L12:M12) -> 0 | O12: 0 | P12: 0 | Q12: =SUM(O12:P12) -> 0 | R12: 0 | S12: 0 | T12: =R12+S12 -> 0 | U12: 0 | V12: 0 | W12: =U12+V12 -> 0 | X12: 0 | Y12: 0 | Z12: =X12+Y12 -> 0 | AA12: 0 | AB12: 0 | AC12: =AA12+AB12 -> 0
B13: March | C13: 0 | D13: 0 | E13: =SUM(C13:D13) -> 0 | F13: 0 | G13: 0 | H13: =SUM(F13:G13) -> 0 | I13: 0 | J13: 0 | K13: =SUM(I13:J13) -> 0 | L13: 0 | M13: 0 | N13: =SUM(L13:M13) -> 0 | O13: 0 | P13: 0 | Q13: =SUM(O13:P13) -> 0 | R13: 0 | S13: 0 | T13: =R13+S13 -> 0 | U13: 0 | V13: 0 | W13: =U13+V13 -> 0 | X13: 0 | Y13: 0 | Z13: =X13+Y13 -> 0 | AA13: 0 | AB13: 0 | AC13: =AA13+AB13 -> 0
B14: Total 1st Quarter | C14: =SUM(C11:C13) -> 0 | D14: =SUM(D11:D13) -> 0 | E14: =SUM(C14:D14) -> 0 | F14: =SUM(F11:F13) -> 0 | G14: =SUM(G11:G13) -> 0 | H14: =SUM(F14:G14) -> 0 | I14: =SUM(I11:I13) -> 0 | J14: =SUM(J11:J13) -> 0 | K14: =SUM(I14:J14) -> 0 | L14: =SUM(L11:L13) -> 0 | M14: =SUM(M11:M13) -> 0 | N14: =SUM(L14:M14) -> 0 | O14: =SUM(O11:O13) -> 0 | P14: =SUM(P11:P13) -> 0 | Q14: =SUM(O14:P14) -> 0 | R14: =SUM(R11:R13) -> 0 | S14: =SUM(S11:S13) -> 0 | T14: =R14+S14 -> 0 | U14: =SUM(U11:U13) -> 0 | V14: =SUM(V11:V13) -> 0 | W14: =U14+V14 -> 0 | X14: =SUM(X11:X13) -> 0 | Y14: =SUM(Y11:Y13) -> 0 | Z14: =X14+Y14 -> 0 | AA14: =SUM(AA11:AA13) -> 0 | AB14: =SUM(AB11:AB13) -> 0 | AC14: =AA14+AB14 -> 0
B15: April | C15: 0 | D15: 0 | E15: =SUM(C15:D15) -> 0 | F15: 0 | G15: 0 | H15: =SUM(F15:G15) -> 0 | I15: 0 | J15: 0 | K15: =SUM(I15:J15) -> 0 | L15: 0 | M15: 0 | N15: =SUM(L15:M15) -> 0 | O15: 0 | P15: 0 | Q15: =SUM(O15:P15) -> 0 | R15: 0 | S15: 0 | T15: =R15+S15 -> 0 | U15: 0 | V15: 0 | W15: =U15+V15 -> 0 | X15: 0 | Y15: 0 | Z15: =X15+Y15 -> 0 | AA15: 0 | AB15: 0 | AC15: =AA15+AB15 -> 0
B16: May | C16: 0 | D16: 0 | E16: =SUM(C16:D16) -> 0 | F16: 0 | G16: 0 | H16: =SUM(F16:G16) -> 0 | I16: 0 | J16: 0 | K16: =SUM(I16:J16) -> 0 | L16: 0 | M16: 0 | N16: =SUM(L16:M16) -> 0 | O16: 0 | P16: 0 | Q16: =SUM(O16:P16) -> 0 | R16: 0 | S16: 0 | T16: =R16+S16 -> 0 | U16: 0 | V16: 0 | W16: =U16+V16 -> 0 | X16: 0 | Y16: 0 | Z16: =X16+Y16 -> 0 | AA16: 0 | AB16: 0 | AC16: =AA16+AB16 -> 0
B17: June | C17: 0 | D17: 0 | E17: =SUM(C17:D17) -> 0 | F17: 0 | G17: 0 | H17: =SUM(F17:G17) -> 0 | I17: 0 | J17: 0 | K17: =SUM(I17:J17) -> 0 | L17: 0 | M17: 0 | N17: =SUM(L17:M17) -> 0 | O17: 0 | P17: 0 | Q17: =SUM(O17:P17) -> 0 | R17: 0 | S17: 0 | T17: =R17+S17 -> 0 | U17: 0 | V17: 0 | W17: =U17+V17 -> 0 | X17: 0 | Y17: 0 | Z17: =X17+Y17 -> 0 | AA17: 0 | AB17: 0 | AC17: =AA17+AB17 -> 0
B18: Total 2nd Quarter | C18: =SUM(C15:C17) -> 0 | D18: =SUM(D15:D17) -> 0 | E18: =SUM(C18:D18) -> 0 | F18: =SUM(F15:F17) -> 0 | G18: =SUM(G15:G17) -> 0 | H18: =SUM(F18:G18) -> 0 | I18: =SUM(I15:I17) -> 0 | J18: =SUM(J15:J17) -> 0 | K18: =SUM(I18:J18) -> 0 | L18: =SUM(L15:L17) -> 0 | M18: =SUM(M15:M17) -> 0 | N18: =SUM(L18:M18) -> 0 | O18: =SUM(O15:O17) -> 0 | P18: =SUM(P15:P17) -> 0 | Q18: =SUM(O18:P18) -> 0 | R18: =SUM(R15:R17) -> 0 | S18: =SUM(S15:S17) -> 0 | T18: =R18+S18 -> 0 | U18: =SUM(U15:U17) -> 0 | V18: =SUM(V15:V17) -> 0 | W18: =U18+V18 -> 0 | X18: =SUM(X15:X17) -> 0 | Y18: =SUM(Y15:Y17) -> 0 | Z18: =X18+Y18 -> 0 | AA18: =SUM(AA15:AA17) -> 0 | AB18: =SUM(AB15:AB17) -> 0 | AC18: =AA18+AB18 -> 0
B19: July | C19: 0 | D19: 0 | E19: =SUM(C19:D19) -> 0 | F19: 0 | G19: 0 | H19: =SUM(F19:G19) -> 0 | I19: 0 | J19: 0 | K19: =SUM(I19:J19) -> 0 | L19: ='Jul25'!O25 -> 0 | M19: ='Jul25'!P25 -> 0 | N19: =SUM(L19:M19) -> 0 | O19: ='Jul25'!R25 -> 0 | P19: ='Jul25'!S25 -> 0 | Q19: =SUM(O19:P19) -> 0 | R19: ='Jul25'!R25 -> 0 | S19: ='Jul25'!S25 -> 0 | T19: =R19+S19 -> 0 | U19: ='Jul25'!U25 -> 0 | V19: ='Jul25'!V25 -> 0 | W19: =U19+V19 -> 0 | X19: ='Jul25'!AA25 -> 0 | Y19: ='Jul25'!AB25 -> 0 | Z19: =X19+Y19 -> 0 | AA19: ='Jul25'!AG25 -> 0 | AB19: ='Jul25'!AH25 -> 0 | AC19: =AA19+AB19 -> 0
B20: August | C20: 0 | D20: 0 | E20: =SUM(C20:D20) -> 0 | F20: 0 | G20: 0 | H20: =SUM(F20:G20) -> 0 | I20: 0 | J20: 0 | K20: =SUM(I20:J20) -> 0 | L20: ='Aug25'!O25 -> 0 | M20: ='Aug25'!P25 -> 0 | N20: =SUM(L20:M20) -> 0 | O20: ='Aug25'!R25 -> 0 | P20: ='Aug25'!S25 -> 0 | Q20: =SUM(O20:P20) -> 0 | R20: ='Aug25'!R25 -> 0 | S20: ='Aug25'!S25 -> 0 | T20: =R20+S20 -> 0 | U20: ='Aug25'!U25 -> 0 | V20: ='Aug25'!V25 -> 0 | W20: =U20+V20 -> 0 | X20: ='Aug25'!AA25 -> 0 | Y20: ='Aug25'!AB25 -> 0 | Z20: =X20+Y20 -> 0 | AA20: ='Aug25'!AG25 -> 0 | AB20: ='Aug25'!AH25 -> 0 | AC20: =AA20+AB20 -> 0
B21: September | C21: ='Sep24'!F42 -> 9010 | D21: ='Sep24'!G42 -> 25023 | E21: =SUM(C21:D21) -> 34033 | F21: ='Sep24'!I42 -> 289870 | G21: ='Sep24'!J42 -> 875805 | H21: =SUM(F21:G21) -> 1165675 | I21: ='Sep24'!L42 -> 152727 | J21: ='Sep24'!M42 -> 509984 | K21: =SUM(I21:J21) -> 662711 | L21: ='Sep24'!O42 -> 27020.504 | M21: ='Sep24'!P42 -> 80688.849 | N21: =SUM(L21:M21) -> 107709.35 | O21: ='Sep24'!R42 -> 125706.5 | P21: ='Sep24'!S42 -> 429295.15 | Q21: =SUM(O21:P21) -> 555001.65 | R21: ='Sep24'!U42 -> 69138.573 | S21: ='Sep24'!V42 -> 236112.33 | T21: =R21+S21 -> 305250.91 | U21: ='Sep24'!X42 -> 72777.445 | V21: ='Sep24'!Y42 -> 248539.3 | W21: =U21+V21 -> 321316.74 | X21: ='Sep24'!AD42 -> 63950.567 | Y21: ='Sep24'!AE42 -> 224124.37 | Z21: =X21+Y21 -> 288074.94 | AA21: ='Sep24'!AJ42 -> 2276 | AB21: ='Sep24'!AK42 -> 8081.057 | AC21: =AA21+AB21 -> 10357.057
B22: Total 3rd Quarter | C22: =SUM(C19:C21) -> 9010 | D22: =SUM(D19:D21) -> 25023 | E22: =SUM(C22:D22) -> 34033 | F22: =SUM(F19:F21) -> 289870 | G22: =SUM(G19:G21) -> 875805 | H22: =SUM(F22:G22) -> 1165675 | I22: =SUM(I19:I21) -> 152727 | J22: =SUM(J19:J21) -> 509984 | K22: =SUM(I22:J22) -> 662711 | L22: =SUM(L19:L21) -> 27020.504 | M22: =SUM(M19:M21) -> 80688.849 | N22: =SUM(L22:M22) -> 107709.35 | O22: =SUM(O19:O21) -> 125706.5 | P22: =SUM(P19:P21) -> 429295.15 | Q22: =SUM(O22:P22) -> 555001.65 | R22: =SUM(R19:R21) -> 69138.573 | S22: =SUM(S19:S21) -> 236112.33 | T22: =R22+S22 -> 305250.91 | U22: =SUM(U19:U21) -> 72777.445 | V22: =SUM(V19:V21) -> 248539.3 | W22: =U22+V22 -> 321316.74 | X22: =SUM(X19:X21) -> 63950.567 | Y22: =SUM(Y19:Y21) -> 224124.37 | Z22: =X22+Y22 -> 288074.94 | AA22: =SUM(AA19:AA21) -> 2276 | AB22: =SUM(AB19:AB21) -> 8081.057 | AC22: =AA22+AB22 -> 10357.057
B23: October | C23: ='Oct24'!F43 -> 31266 | D23: ='Oct24'!G43 -> 0 | E23: =SUM(C23:D23) -> 31266 | F23: ='Oct24'!L43 -> 594292 | G23: ='Oct24'!M43 -> 0 | H23: =SUM(F23:G23) -> 594292 | I23: ='Oct24'!L43 -> 594292 | J23: ='Oct24'!M43 -> 0 | K23: =SUM(I23:J23) -> 594292 | L23: ='Oct24'!O43 -> 54986.331 | M23: ='Oct24'!P43 -> 0 | N23: =SUM(L23:M23) -> 54986.331 | O23: ='Oct24'!R43 -> 404236.67 | P23: ='Oct24'!S43 -> 0 | Q23: =SUM(O23:P23) -> 404236.67 | R23: ='Oct24'!U43 -> 222330.17 | S23: ='Oct24'!V43 -> 0 | T23: =R23+S23 -> 222330.17 | U23: ='Oct24'!X43 -> 234031.76 | V23: ='Oct24'!Y43 -> 0 | W23: =U23+V23 -> 234031.76 | X23: ='Oct24'!AD43 -> 112756.9 | Y23: ='Oct24'!AE43 -> 0 | Z23: =X23+Y23 -> 112756.9 | AA23: ='Oct24'!AJ43 -> 4022 | AB23: ='Oct24'!AK43 -> 0 | AC23: =AA23+AB23 -> 4022
B24: November | C24: ='Nov24'!F42 -> 27439 | D24: ='Nov24'!G42 -> 0 | E24: =SUM(C24:D24) -> 27439 | F24: ='Nov24'!L42 -> 850851 | G24: ='Nov24'!M42 -> 0 | H24: =SUM(F24:G24) -> 850851 | I24: ='Nov24'!L42 -> 850851 | J24: ='Nov24'!M42 -> 0 | K24: =SUM(I24:J24) -> 850851 | L24: ='Nov24'!O42 -> 105369.06 | M24: ='Nov24'!P42 -> 0 | N24: =SUM(L24:M24) -> 105369.06 | O24: ='Nov24'!R42 -> 745481.94 | P24: ='Nov24'!S42 -> 0 | Q24: =SUM(O24:P24) -> 745481.94 | R24: ='Nov24'!U42 -> 410015.06 | S24: ='Nov24'!V42 -> 0 | T24: =R24+S24 -> 410015.06 | U24: ='Nov24'!X42 -> 431594.8 | V24: ='Nov24'!Y42 -> 0 | W24: =U24+V24 -> 431594.8 | X24: ='Nov24'!AD42 -> 237987.47 | Y24: ='Nov24'!AE42 -> 0 | Z24: =X24+Y24 -> 237987.47 | AA24: ='Nov24'!AJ42 -> 8436 | AB24: ='Nov24'!AK42 -> 0 | AC24: =AA24+AB24 -> 8436
B25: December | C25: ='Dec24'!F43 -> 25326 | D25: ='Dec24'!G43 -> 0 | E25: =SUM(C25:D25) -> 25326 | F25: ='Dec24'!L43 -> 725315 | G25: ='Dec24'!M43 -> 0 | H25: =SUM(F25:G25) -> 725315 | I25: ='Dec24'!L43 -> 725315 | J25: ='Dec24'!M43 -> 0 | K25: =SUM(I25:J25) -> 725315 | L25: ='Dec24'!O43 -> 98139.209 | M25: ='Dec24'!P43 -> 0 | N25: =SUM(L25:M25) -> 98139.209 | O25: ='Dec24'!R43 -> 628143.79 | P25: ='Dec24'!S43 -> 0 | Q25: =SUM(O25:P25) -> 628143.79 | R25: ='Dec24'!U43 -> 345479.09 | S25: ='Dec24'!V43 -> 0 | T25: =R25+S25 -> 345479.09 | U25: ='Dec24'!X43 -> 363662.2 | V25: ='Dec24'!Y43 -> 0 | W25: =U25+V25 -> 363662.2 | X25: ='Dec24'!AD43 -> 159515.09 | Y25: ='Dec24'!AE43 -> 0 | Z25: =X25+Y25 -> 159515.09 | AA25: ='Dec24'!AJ43 -> 5656 | AB25: ='Dec24'!AK43 -> 0 | AC25: =AA25+AB25 -> 5656
B26: Total 4th Quarter | C26: =SUM(C23:C25) -> 84031 | D26: =SUM(D23:D25) -> 0 | E26: =SUM(C26:D26) -> 84031 | F26: =SUM(F23:F25) -> 2170458 | G26: =SUM(G23:G25) -> 0 | H26: =SUM(F26:G26) -> 2170458 | I26: =SUM(I23:I25) -> 2170458 | J26: =SUM(J23:J25) -> 0 | K26: =SUM(I26:J26) -> 2170458 | L26: =SUM(L23:L25) -> 258494.6 | M26: =SUM(M23:M25) -> 0 | N26: =SUM(L26:M26) -> 258494.6 | O26: =SUM(O23:O25) -> 1777862.4 | P26: =SUM(P23:P25) -> 0 | Q26: =SUM(O26:P26) -> 1777862.4 | R26: =SUM(R23:R25) -> 977824.32 | S26: =SUM(S23:S25) -> 0 | T26: =R26+S26 -> 977824.32 | U26: =SUM(U23:U25) -> 1029288.8 | V26: =SUM(V23:V25) -> 0 | W26: =U26+V26 -> 1029288.8 | X26: =SUM(X23:X25) -> 510259.46 | Y26: =SUM(Y23:Y25) -> 0 | Z26: =X26+Y26 -> 510259.46 | AA26: =SUM(AA23:AA25) -> 18114 | AB26: =SUM(AB23:AB25) -> 0 | AC26: =AA26+AB26 -> 18114
B27: Total 2024 | C27: =C14+C18+C22+C26 -> 93041 | D27: =D14+D18+D22+D26 -> 25023 | E27: =E14+E18+E22+E26 -> 118064 | F27: =F14+F18+F22+F26 -> 2460328 | G27: =G14+G18+G22+G26 -> 875805 | H27: =H14+H18+H22+H26 -> 3336133 | I27: =I14+I18+I22+I26 -> 2323185 | J27: =J14+J18+J22+J26 -> 509984 | ... AC27: =AC14+AC18+AC22+AC26 -> 28471.057 | AE27: =Z27/W27*100 -> 59.10937
B29: January | C29: ='Jan25'!F43 -> 21206 | D29: ='Jan25'!G43 -> 0 | E29: =SUM(C29:D29) -> 21206 | F29: ='Jan25'!I43 -> 742210 | G29: ='Jan25'!J43 -> 0 | H29: =SUM(F29:G29) -> 742210 | I29: ='Jan25'!L43 -> 542487 | J29: ='Jan25'!M43 -> 0 | K29: =SUM(I29:J29) -> 542487 | L29: ='Jan25'!O43 -> 66158.633 | M29: ='Jan25'!P43 -> 0 | N29: =SUM(L29:M29) -> 66158.633 | O29: ='Jan25'!R43 -> 476328.37 | P29: ='Jan25'!S43 -> 0 | Q29: =SUM(O29:P29) -> 476328.37 | R29: ='Jan25'!U43 -> 261980.6 | S29: ='Jan25'!V43 -> 0 | T29: =R29+S29 -> 261980.6 | U29: ='Jan25'!X43 -> 275769.05 | V29: ='Jan25'!Y43 -> 0 | W29: =U29+V29 -> 275769.05 | X29: ='Jan25'!AD43 -> 64273.53 | Y29: ='Jan25'!AE43 -> 0 | Z29: =X29+Y29 -> 64273.53 | AA29: ='Jan25'!AJ43 -> 2323 | AB29: ='Jan25'!AK43 -> 0 | AC29: =AA29+AB29 -> 2323
B30: February | C30: ='Feb25'!F40 -> 17391 | D30: ='Feb25'!G40 -> 0 | E30: =SUM(C30:D30) -> 17391 | F30: ='Feb25'!I40 -> 608685 | G30: ='Feb25'!J40 -> 0 | H30: =SUM(F30:G30) -> 608685 | I30: ='Feb25'!L40 -> 242195 | J30: ='Feb25'!M40 -> 0 | K30: =SUM(I30:J30) -> 242195 | L30: ='Feb25'!O40 -> 31257.194 | M30: ='Feb25'!P40 -> 0 | N30: =SUM(L30:M30) -> 31257.194 | O30: ='Feb25'!R40 -> 210937.81 | P30: ='Feb25'!S40 -> 0 | Q30: =SUM(O30:P30) -> 210937.81 | R30: ='Feb25'!U40 -> 116015.79 | S30: ='Feb25'!V40 -> 0 | T30: =R30+S30 -> 116015.79 | U30: ='Feb25'!X40 -> 122121.89 | V30: ='Feb25'!Y40 -> 0 | W30: =U30+V30 -> 122121.89 | X30: ='Feb25'!AD40 -> 40498.864 | Y30: ='Feb25'!AE40 -> 0 | Z30: =X30+Y30 -> 40498.864 | AA30: ='Feb25'!AJ40 -> 1432 | AB30: ='Feb25'!AK40 -> 0 | AC30: =AA30+AB30 -> 1432
B31: March | C31: ='Mar25'!F43 -> 26446 | D31: ='Mar25'!G43 -> 0 | E31: =SUM(C31:D31) -> 26446 | F31: ='Mar25'!L43 -> 599848.7 | G31: ='Mar25'!M43 -> 0 | H31: =SUM(F31:G31) -> 599848.7 | I31: ='Mar25'!L43 -> 599848.7 | J31: ='Mar25'!M43 -> 0 | K31: =SUM(I31:J31) -> 599848.7 | L31: ='Mar25'!O43 -> 79359.353 | M31: ='Mar25'!P43 -> 0 | N31: =SUM(L31:M31) -> 79359.353 | O31: ='Mar25'!R43 -> 520489.35 | P31: ='Mar25'!S43 -> 0 | Q31: =SUM(O31:P31) -> 520489.35 | R31: ='Mar25'!U43 -> 286269.14 | S31: ='Mar25'!V43 -> 0 | T31: =R31+S31 -> 286269.14 | U31: ='Mar25'!X43 -> 301335.94 | V31: ='Mar25'!Y43 -> 0 | W31: =U31+V31 -> 301335.94 | X31: ='Mar25'!AD43 -> 78243.7 | Y31: ='Mar25'!AE43 -> 0 | Z31: =X31+Y31 -> 78243.7 | AA31: ='Mar25'!AJ43 -> 2780 | AB31: ='Mar25'!AK43 -> 0 | AC31: =AA31+AB31 -> 2780
B32: Total 1st Quarter | C32: =SUM(C29:C31) -> 65043 | D32: =SUM(D29:D31) -> 0 | E32: =SUM(C32:D32) -> 65043 | F32: =SUM(F29:F31) -> 1950743.7 | G32: =SUM(G29:G31) -> 0 | H32: =SUM(F32:G32) -> 1950743.7 | I32: =SUM(I29:I31) -> 1384530.7 | J32: =SUM(J29:J31) -> 0 | K32: =SUM(I32:J32) -> 1384530.7 | L32: =SUM(L29:L31) -> 176775.18 | M32: =SUM(M29:M31) -> 0 | N32: =SUM(L32:M32) -> 176775.18 | O32: =SUM(O29:O31) -> 1207755.5 | P32: =SUM(P29:P31) -> 0 | Q32: =SUM(O32:P32) -> 1207755.5 | R32: =SUM(R29:R31) -> 664265.54 | S32: =SUM(S29:S31) -> 0 | T32: =R32+S32 -> 664265.54 | U32: =SUM(U29:U31) -> 699226.88 | V32: =SUM(V29:V31) -> 0 | W32: =U32+V32 -> 699226.88 | X32: =SUM(X29:X31) -> 183016.09 | Y32: =SUM(Y29:Y31) -> 0 | Z32: =X32+Y32 -> 183016.09 | AA32: =SUM(AA29:AA31) -> 6535 | AB32: =SUM(AB29:AB31) -> 0 | AC32: =AA32+AB32 -> 6535
B33: April | C33: ='Apr25'!F42 -> 30280 | D33: ='Apr25'!G42 -> 0 | E33: =SUM(C33:D33) -> 30280 | F33: ='Apr25'!I42 -> 1011360 | G33: ='Apr25'!J42 -> 0 | H33: =SUM(F33:G33) -> 1011360 | I33: ='Apr25'!L42 -> 592910 | J33: ='Apr25'!M42 -> 0 | K33: =SUM(I33:J33) -> 592910 | L33: ='Apr25'!O42 -> 74256.115 | M33: ='Apr25'!P42 -> 0 | N33: =SUM(L33:M33) -> 74256.115 | O33: ='Apr25'!R42 -> 518653.88 | P33: ='Apr25'!S42 -> 0 | Q33: =SUM(O33:P33) -> 518653.88 | R33: ='Apr25'!U42 -> 285259.64 | S33: ='Apr25'!V42 -> 0 | T33: =R33+S33 -> 285259.64 | U33: ='Apr25'!X42 -> 300273.3 | V33: ='Apr25'!Y42 -> 0 | W33: =U33+V33 -> 300273.3 | X33: ='Apr25'!AD42 -> 78004.354 | Y33: ='Apr25'!AE42 -> 0 | Z33: =X33+Y33 -> 78004.354 | AA33: ='Apr25'!AJ42 -> 2768 | AB33: ='Apr25'!AK42 -> 0 | AC33: =AA33+AB33 -> 2768
B34: May | C34: ='May25'!F43 -> 29279 | D34: ='May25'!G43 -> 0 | E34: =SUM(C34:D34) -> 29279 | F34: ='May25'!I43 -> 1024765 | G34: ='May25'!J43 -> 0 | H34: =SUM(F34:G34) -> 1024765 | I34: ='May25'!L43 -> 758860 | J34: ='May25'!M43 -> 0 | K34: =SUM(I34:J34) -> 758860 | L34: ='May25'!O43 -> 107080.94 | M34: ='May25'!P43 -> 0 | N34: =SUM(L34:M34) -> 107080.94 | O34: ='May25'!R43 -> 651779.06 | P34: ='May25'!S43 -> 0 | Q34: =SUM(O34:P34) -> 651779.06 | R34: ='May25'!U43 -> 358478.49 | S34: ='May25'!V43 -> 0 | T34: =R34+S34 -> 358478.49 | U34: ='Apr25'!X42 -> 300273.3 | V34: ='Apr25'!Y42 -> 0 | W34: =U34+V34 -> 300273.3 | X34: ='May25'!AD43 -> 155628.39 | Y34: ='May25'!AE43 -> 0 | Z34: =X34+Y34 -> 155628.39 | AA34: ='May25'!AJ43 -> 5573 | AB34: ='May25'!AK43 -> 0 | AC34: =AA34+AB34 -> 5573
B35: June | C35: ='Jun25'!F42 -> 0 | D35: ='Jun25'!G42 -> 0 | E35: =SUM(C35:D35) -> 0 | F35: ='Jun25'!L42 -> 0 | G35: ='Jun25'!M42 -> 0 | H35: =SUM(F35:G35) -> 0 | I35: ='Jun25'!O42 -> 0 | J35: ='Jun25'!P42 -> 0 | K35: =SUM(I35:J35) -> 0 | L35: ='Jun25'!O42 -> 0 | M35: ='Jun25'!P42 -> 0 | N35: =SUM(L35:M35) -> 0 | O35: ='Jun25'!R42 -> 0 | P35: ='Jun25'!S42 -> 0 | Q35: =SUM(O35:P35) -> 0 | R35: ='Jun25'!R42 -> 0 | S35: ='Jun25'!S42 -> 0 | T35: =R35+S35 -> 0 | U35: ='Jun25'!U42 -> 0 | V35: ='Jun25'!V42 -> 0 | W35: =U35+V35 -> 0 | X35: ='Jun25'!AA42 -> 0 | Y35: ='Jun25'!AB42 -> 0 | Z35: =X35+Y35 -> 0 | AA35: ='Jun25'!AG42 -> 0 | AB35: ='Jun25'!AH42 -> 0 | AC35: =AA35+AB35 -> 0
B36: Total 2nd Quarter | C36: =SUM(C33:C35) -> 59559 | D36: =SUM(D33:D35) -> 0 | E36: =SUM(C36:D36) -> 59559 | F36: =SUM(F33:F35) -> 2036125 | G36: =SUM(G33:G35) -> 0 | H36: =SUM(F36:G36) -> 2036125 | I36: =SUM(I33:I35) -> 1351770 | J36: =SUM(J33:J35) -> 0 | K36: =SUM(I36:J36) -> 1351770 | L36: =SUM(L33:L35) -> 181337.05 | M36: =SUM(M33:M35) -> 0 | N36: =SUM(L36:M36) -> 181337.05 | O36: =SUM(O33:O35) -> 1170432.9 | P36: =SUM(P33:P35) -> 0 | Q36: =SUM(O36:P36) -> 1170432.9 | R36: =SUM(R33:R35) -> 643738.12 | S36: =SUM(S33:S35) -> 0 | T36: =R36+S36 -> 643738.12 | U36: =SUM(U33:U35) -> 600546.6 | V36: =SUM(V33:V35) -> 0 | W36: =U36+V36 -> 600546.6 | X36: =SUM(X33:X35) -> 233632.75 | Y36: =SUM(Y33:Y35) -> 0 | Z36: =X36+Y36 -> 233632.75 | AA36: =SUM(AA33:AA35) -> 8341 | AB36: =SUM(AB33:AB35) -> 0 | AC36: =AA36+AB36 -> 8341
B37: July | C37: ='Jul25'!F43 -> 0 | D37: ='Jul25'!G43 -> 0 | E37: =SUM(C37:D37) -> 0 | F37: ='Jul25'!L43 -> 0 | G37: ='Jul25'!M43 -> 0 | H37: =SUM(F37:G37) -> 0 | I37: ='Jul25'!O43 -> 0 | J37: ='Jul25'!P43 -> 0 | K37: =SUM(I37:J37) -> 0 | L37: ='Jul25'!O43 -> 0 | M37: ='Jul25'!P43 -> 0 | N37: =SUM(L37:M37) -> 0 | O37: ='Jul25'!R43 -> 0 | P37: ='Jul25'!S43 -> 0 | Q37: =SUM(O37:P37) -> 0 | R37: ='Jul25'!R43 -> 0 | S37: ='Jul25'!S43 -> 0 | T37: =R37+S37 -> 0 | U37: ='Jul25'!U43 -> 0 | V37: ='Jul25'!V43 -> 0 | W37: =U37+V37 -> 0 | X37: ='Jul25'!AA43 -> 0 | Y37: ='Jul25'!AB43 -> 0 | Z37: =X37+Y37 -> 0 | AA37: ='Jul25'!AG43 -> 0 | AB37: ='Jul25'!AH43 -> 0 | AC37: =AA37+AB37 -> 0
B38: August | C38: ='Aug25'!F43 -> 0 | D38: ='Aug25'!G43 -> 0 | E38: =SUM(C38:D38) -> 0 | F38: ='Aug25'!L43 -> 0 | G38: ='Aug25'!M43 -> 0 | H38: =SUM(F38:G38) -> 0 | I38: ='Aug25'!O43 -> 0 | J38: ='Aug25'!P43 -> 0 | K38: =SUM(I38:J38) -> 0 | L38: ='Aug25'!O43 -> 0 | M38: ='Aug25'!P43 -> 0 | N38: =SUM(L38:M38) -> 0 | O38: ='Aug25'!R43 -> 0 | P38: ='Aug25'!S43 -> 0 | Q38: =SUM(O38:P38) -> 0 | R38: ='Aug25'!R43 -> 0 | S38: ='Aug25'!S43 -> 0 | T38: =R38+S38 -> 0 | U38: ='Aug25'!U43 -> 0 | V38: ='Aug25'!V43 -> 0 | W38: =U38+V38 -> 0 | X38: ='Aug25'!AA43 -> 0 | Y38: ='Aug25'!AB43 -> 0 | Z38: =X38+Y38 -> 0 | AA38: ='Aug25'!AG43 -> 0 | AB38: ='Aug25'!AH43 -> 0 | AC38: =AA38+AB38 -> 0
B39: September | C39: ='Sep24'!E59 | D39: ='Sep24'!F59 | E39: =SUM(C39:D39) -> 0 | F39: ='Sep24'!K59 | G39: ='Sep24'!L59 | H39: =SUM(F39:G39) -> 0 | I39: ='Sep24'!N59 | J39: ='Sep24'!O59 | K39: =SUM(I39:J39) -> 0 | L39: ='Sep24'!N59 | M39: ='Sep24'!O59 | N39: =SUM(L39:M39) -> 0 | O39: ='Sep24'!Q59 | P39: ='Sep24'!R59 | Q39: =SUM(O39:P39) -> 0 | R39: ='Sep24'!Q59 | S39: ='Sep24'!R59 | T39: =R39+S39 -> 0 | U39: ='Sep24'!T59 | V39: ='Sep24'!U59 | W39: =U39+V39 -> 0 | X39: ='Sep24'!AC59 | Y39: ='Sep24'!AD59 | Z39: =X39+Y39 -> 0 | AA39: ='Sep24'!AI59 | AB39: ='Sep24'!AJ59 | AC39: =AA39+AB39 -> 0
B40: Total 3rd Quarter | C40: =SUM(C39) -> 0 | D40: =SUM(D39) -> 0 | E40: =SUM(C40:D40) -> 0 | F40: =SUM(F39) -> 0 | G40: =SUM(G39) -> 0 | H40: =SUM(F40:G40) -> 0 | I40: =SUM(I39) -> 0 | J40: =SUM(J39) -> 0 | K40: =SUM(I40:J40) -> 0 | L40: =SUM(L39) -> 0 | M40: =SUM(M39) -> 0 | N40: =SUM(L40:M40) -> 0 | O40: =SUM(O39) -> 0 | P40: =SUM(P39) -> 0 | Q40: =SUM(O40:P40) -> 0 | R40: =SUM(R37:R39) -> 0 | S40: =SUM(S39) -> 0 | T40: =R40+S40 -> 0 | U40: =SUM(U39) -> 0 | V40: =SUM(V39) -> 0 | W40: =U40+V40 -> 0 | X40: =SUM(X39) -> 0 | Y40: =SUM(Y39) -> 0 | Z40: =X40+Y40 -> 0 | AA40: =SUM(AA39) -> 0 | AB40: =SUM(AB39) -> 0 | AC40: =AA40+AB40 -> 0
B41: October | C41: ='Oct24'!E60 | D41: ='Oct24'!F60 | E41: =SUM(C41:D41) -> 0 | F41: ='Oct24'!K60 | G41: ='Oct24'!L60 | H41: =SUM(F41:G41) -> 0 | I41: ='Oct24'!N60 | J41: ='Oct24'!O60 | K41: =SUM(I41:J41) -> 0 | L41: ='Oct24'!N60 | M41: ='Oct24'!O60 | N41: =SUM(L41:M41) -> 0 | O41: ='Oct24'!Q60 | P41: ='Oct24'!R60 | Q41: =SUM(O41:P41) -> 0 | R41: 0 | S41: 0 | T41: =R41+S41 -> 0 | U41: 0 | V41: 0 | W41: =U41+V41 -> 0 | X41: ='Oct24'!AC60 | Y41: ='Oct24'!AD60 | Z41: =X41+Y41 -> 0 | AA41: ='Oct24'!AI60 | AB41: ='Oct24'!AJ60 | AC41: =AA41+AB41 -> 0
B42: November | C42: ='Nov24'!E59 | D42: ='Nov24'!F59 | E42: =SUM(C42:D42) -> 0 | F42: ='Nov24'!K59 | G42: ='Nov24'!L59 | H42: =SUM(F42:G42) -> 0 | I42: ='Nov24'!N59 | J42: ='Nov24'!O59 | K42: =SUM(I42:J42) -> 0 | L42: ='Nov24'!N59 | M42: ='Nov24'!O59 | N42: =SUM(L42:M42) -> 0 | O42: ='Nov24'!Q59 | P42: ='Nov24'!R59 | Q42: =SUM(O42:P42) -> 0 | R42: 0 | S42: 0 | T42: =R42+S42 -> 0 | U42: 0 | V42: 0 | W42: =U42+V42 -> 0 | X42: ='Nov24'!AC59 | Y42: ='Nov24'!AD59 | Z42: =X42+Y42 -> 0 | AA42: ='Nov24'!AI59 | AB42: ='Nov24'!AJ59 | AC42: =AA42+AB42 -> 0
B43: December | C43: ='Dec24'!F60 | D43: ='Dec24'!G60 | E43: =SUM(C43:D43) -> 0 | F43: ='Dec24'!L60 | G43: ='Dec24'!M60 | H43: =SUM(F43:G43) -> 0 | I43: ='Dec24'!O60 | J43: ='Dec24'!P60 | K43: =SUM(I43:J43) -> 0 | L43: ='Dec24'!O60 | M43: ='Dec24'!P60 | N43: =SUM(L43:M43) -> 0 | O43: ='Dec24'!R60 | P43: ='Dec24'!S60 | Q43: =SUM(O43:P43) -> 0 | R43: 0 | S43: 0 | T43: =R43+S43 -> 0 | U43: 0 | V43: 0 | W43: =U43+V43 -> 0 | X43: ='Dec24'!AD60 | Y43: ='Dec24'!AE60 | Z43: =X43+Y43 -> 0 | AA43: ='Dec24'!AJ60 | AB43: ='Dec24'!AK60 | AC43: =AA43+AB43 -> 0
B44: Total 4th Quarter | C44: =SUM(C41:C43) -> 0 | D44: =SUM(D41:D43) -> 0 | E44: =SUM(C44:D44) -> 0 | F44: =SUM(F41:F43) -> 0 | G44: =SUM(G41:G43) -> 0 | H44: =SUM(F44:G44) -> 0 | I44: =SUM(I41:I43) -> 0 | J44: =SUM(J41:J43) -> 0 | K44: =SUM(I44:J44) -> 0 | L44: =SUM(L41:L43) -> 0 | M44: =SUM(M41:M43) -> 0 | N44: =SUM(L44:M44) -> 0 | O44: =SUM(O41:O43) -> 0 | P44: =SUM(P41:P43) -> 0 | Q44: =SUM(O44:P44) -> 0 | R44: =SUM(R41:R43) -> 0 | S44: =SUM(S41:S43) -> 0 | T44: =R44+S44 -> 0 | U44: =SUM(U41:U43) -> 0 | V44: =SUM(V41:V43) -> 0 | W44: =U44+V44 -> 0 | X44: =SUM(X41:X43) -> 0 | Y44: =SUM(Y41:Y43) -> 0 | Z44: =X44+Y44 -> 0 | AA44: =SUM(AA41:AA43) -> 0 | AB44: =SUM(AB41:AB43) -> 0 | AC44: =AA44+AB44 -> 0
B45: Total 2025 | C45: =C32+C36+C40+C44 -> 124602 | D45: =D32+D36+D40+D44 -> 0 | E45: =E32+E36+E40+E44 -> 124602 | F45: =F32+F36+F40+F44 -> 3986868.7 | G45: =G32+G36+G40+G44 -> 0 | H45: =H32+H36+H40+H44 -> 3986868.7 | I45: =I32+I36+I40+I44 -> 2736300.7 | J45: =J32+J36+J40+J44 -> 0 | ... AC45: =AC32+AC36+AC40+AC44 -> 14876 | AE45: =Z45/W45*100 -> 32.055496
B46: OVERALL TOTAL | C46: =SUM(C27,C45) -> 217643 | D46: =SUM(D27,D45) -> 25023 | E46: =SUM(E27,E45) -> 242666 | F46: =SUM(F27,F45) -> 6447196.7 | G46: =SUM(G27,G45) -> 875805 | H46: =SUM(H27,H45) -> 7323001.7 | I46: =SUM(I27,I45) -> 5059485.7 | J46: =SUM(J27,J45) -> 509984 | ... AC46: =SUM(AC27,AC45) -> 43347.057
...

Sheet Sep24
A1: \ | I1: c
B2: Kian Hoe Plantations Berhad (KHPB) | AJ2: GJ to MMBtu
B3: MASS BALANCE (MB) WORKSHEET | AJ3: Conversion Factor | AL3: 1.05506
B4: Year: 2024
B5: DATE | C5: Opening Stock of Biogas (m3) | F5: Incoming POME to Digester (m3) | I5: Biogas Generated (m3) | L5: Biogas Supplied to Scrubber (m3) | O5: Biogas Supplied to Gas Engine (m3) | R5: Biogas Supplied to Biomethane Plant (m3) | U5: Volume CH4 in Raw Biogas (m3) | X5: Biomethane generated (m3) | AA5: Biomethane Supplied to Grid (Sm3) | AD5: Biomethane Supplied to Grid (m3) | AG5: Biomethane Supplied to Grid (GJ) | AJ5: Biomethane Supplied to Grid (MMBtu)
C10: ISCC | D10: NON-ISCC | E10: TOTAL | F10: ISCC | G10: NON-ISCC | H10: TOTAL | I10: ISCC | J10: NON-ISCC | K10: TOTAL | L10: ISCC | M10: NON-ISCC | N10: TOTAL | O10: ISCC | P10: NON-ISCC | Q10: TOTAL | R10: ISCC | S10: NON-ISCC | T10: TOTAL | U10: ISCC | V10: NON-ISCC | W10: TOTAL | X10: ISCC | Y10: NON-ISCC | Z10: TOTAL | AA10: ISCC | AB10: NON-ISCC | AC10: TOTAL | AD10: ISCC | AE10: NON-ISCC | AF10: TOTAL | AG10: ISCC | AH10: NON-ISCC | AI10: TOTAL | AJ10: ISCC | AK10: NON-ISCC | AL10: TOTAL
B11: 45535 | C11: 0 | D11: 45868 | E11: =SUM(C11+D11) -> 45868 | N11: =SUM(L11+M11) -> 0 | Q11: =SUM(O11+P11) -> 0 | T11: =SUM(R11+S11) -> 0 | W11: =SUM(U11+V11) -> 0 | Z11: =SUM(X11+Y11) -> 0 | AC11: =SUM(AA11+AB11) -> 0 | AF11: =SUM(AD11+AE11) -> 0 | AI11: =SUM(AG11+AH11) -> 0 | AL11: =SUM(AJ11+AK11) -> 0
B12: 45536 | E12: =SUM(C12+D12) -> 0 | F12: 0 | G12: 268 | H12: =SUM(F12+G12) -> 268 | I12: =F12*55000*0.35/1000/0.55 -> 0 | J12: =G12*55000*0.35/1000/0.55 -> 9380 | K12: =J12+I12 -> 9380 | L12: 0 | M12: 16259 | N12: =SUM(L12+M12) -> 16259 | O12: 0 | P12: 2398.5612 | Q12: =SUM(O12+P12) -> 2398.5612 | R12: =L12-O12 -> 0 | S12: =M12-P12 -> 13860.439 | T12: =SUM(R12+S12) -> 13860.439 | U12: =R12*0.55 -> 0 | V12: =S12*0.55 -> 7623.2414 | W12: =SUM(U12+V12) -> 7623.2414 | X12: =U12/0.95 -> 0 | Y12: =V12/0.95 -> 8024.4646 | Z12: =SUM(X12+Y12) -> 8024.4646 | AA12: 0 | AB12: 8963.9648 | AC12: =SUM(AA12+AB12) -> 8963.9648 | AD12: =AA12*0.95 -> 0 | AE12: =AB12*0.95 -> 8515.7666 | AF12: =SUM(AD12+AE12) -> 8515.7666 | AG12: 0 | AH12: 324 | AI12: =SUM(AG12+AH12) -> 324 | AJ12: =AG12/1.05506 -> 0 | AK12: =AH12/1.05506 -> 307.09154 | AL12: =SUM(AJ12+AK12) -> 307.09154
B13: 45537 | E13: =SUM(C13+D13) -> 0 | F13: 0 | G13: 530 | H13: =SUM(F13+G13) -> 530 | I13: =F13*55000*0.35/1000/0.55 -> 0 | J13: =G13*55000*0.35/1000/0.55 -> 18550 | K13: =J13+I13 -> 18550 | L13: 0 | M13: 20759 | N13: =SUM(L13+M13) -> 20759 | O13: 0 | P13: 3996.0432 | Q13: =SUM(O13+P13) -> 3996.0432 | R13: =L13-O13 -> 0 | S13: =M13-P13 -> 16762.957 | T13: =SUM(R13+S13) -> 16762.957 | U13: =R13*0.55 -> 0 | V13: =S13*0.55 -> 9219.6263 | W13: =SUM(U13+V13) -> 9219.6263 | X13: =U13/0.95 -> 0 | Y13: =V13/0.95 -> 9704.8697 | Z13: =SUM(X13+Y13) -> 9704.8697 | AA13: 0 | AB13: 10590.438 | AC13: =SUM(AA13+AB13) -> 10590.438 | AD13: =AA13*0.95 -> 0 | AE13: =AB13*0.95 -> 10060.916 | AF13: =SUM(AD13+AE13) -> 10060.916 | AG13: 0 | AH13: 381 | AI13: =SUM(AG13+AH13) -> 381 | AJ13: =AG13/1.05506 -> 0 | AK13: =AH13/1.05506 -> 361.1169 | AL13: =SUM(AJ13+AK13) -> 361.1169
B14: 45538 | E14: =SUM(C14+D14) -> 0 | F14: 0 | G14: 1579 | H14: =SUM(F14+G14) -> 1579 | I14: =F14*55000*0.35/1000/0.55 -> 0 | J14: =G14*55000*0.35/1000/0.55 -> 55265 | K14: =J14+I14 -> 55265 | L14: 0 | M14: 20000 | N14: =SUM(L14+M14) -> 20000 | O14: 0 | P14: 3939.2086 | Q14: =SUM(O14+P14) -> 3939.2086 | R14: =L14-O14 -> 0 | S14: =M14-P14 -> 16060.791 | T14: =SUM(R14+S14) -> 16060.791 | U14: =R14*0.55 -> 0 | V14: =S14*0.55 -> 8833.4353 | W14: =SUM(U14+V14) -> 8833.4353 | X14: =U14/0.95 -> 0 | Y14: =V14/0.95 -> 9298.3529 | Z14: =SUM(X14+Y14) -> 9298.3529 | AA14: 0 | AB14: 10023.997 | AC14: =SUM(AA14+AB14) -> 10023.997 | AD14: =AA14*0.95 -> 0 | AE14: =AB14*0.95 -> 9522.7972 | AF14: =SUM(AD14+AE14) -> 9522.7972 | AG14: 0 | AH14: 361 | AI14: =SUM(AG14+AH14) -> 361 | AJ14: =AG14/1.05506 -> 0 | AK14: =AH14/1.05506 -> 342.16064 | AL14: =SUM(AJ14+AK14) -> 342.16064
B15: 45539 | E15: =SUM(C15+D15) -> 0 | F15: 0 | G15: 1217 | H15: =SUM(F15+G15) -> 1217 | I15: =F15*55000*0.35/1000/0.55 -> 0 | J15: =G15*55000*0.35/1000/0.55 -> 42595 | K15: =J15+I15 -> 42595 | L15: 0 | M15: 22019 | N15: =SUM(L15+M15) -> 22019 | O15: 0 | P15: 3838.1295 | Q15: =SUM(O15+P15) -> 3838.1295 | R15: =L15-O15 -> 0 | S15: =M15-P15 -> 18180.871 | T15: =SUM(R15+S15) -> 18180.871 | U15: =R15*0.55 -> 0 | V15: =S15*0.55 -> 9999.4788 | W15: =SUM(U15+V15) -> 9999.4788 | X15: =U15/0.95 -> 0 | Y15: =V15/0.95 -> 10525.767 | Z15: =SUM(X15+Y15) -> 10525.767 | AA15: 0 | AB15: 11057.338 | AC15: =SUM(AA15+AB15) -> 11057.338 | AD15: =AA15*0.95 -> 0 | AE15: =AB15*0.95 -> 10504.471 | AF15: =SUM(AD15+AE15) -> 10504.471 | AG15: 0 | AH15: 399 | AI15: =SUM(AG15+AH15) -> 399 | AJ15: =AG15/1.05506 -> 0 | AK15: =AH15/1.05506 -> 378.17754 | AL15: =SUM(AJ15+AK15) -> 378.17754
B16: 45540 | E16: =SUM(C16+D16) -> 0 | F16: 0 | G16: 1139 | H16: =SUM(F16+G16) -> 1139 | I16: =F16*55000*0.35/1000/0.55 -> 0 | J16: =G16*55000*0.35/1000/0.55 -> 39865 | K16: =J16+I16 -> 39865 | L16: 0 | M16: 23002 | N16: =SUM(L16+M16) -> 23002 | O16: 0 | P16: 3712.9496 | Q16: =SUM(O16+P16) -> 3712.9496 | R16: =L16-O16 -> 0 | S16: =M16-P16 -> 19289.05 | T16: =SUM(R16+S16) -> 19289.05 | U16: =R16*0.55 -> 0 | V16: =S16*0.55 -> 10608.978 | W16: =SUM(U16+V16) -> 10608.978 | X16: =U16/0.95 -> 0 | Y16: =V16/0.95 -> 11167.345 | Z16: =SUM(X16+Y16) -> 11167.345 | AA16: 0 | AB16: 10811.28 | AC16: =SUM(AA16+AB16) -> 10811.28 | AD16: =AA16*0.95 -> 0 | AE16: =AB16*0.95 -> 10270.716 | AF16: =SUM(AD16+AE16) -> 10270.716 | AG16: 0 | AH16: 392 | AI16: =SUM(AG16+AH16) -> 392 | AJ16: =AG16/1.05506 -> 0 | AK16: =AH16/1.05506 -> 371.54285 | AL16: =SUM(AJ16+AK16) -> 371.54285
B17: 45541 | E17: =SUM(C17+D17) -> 0 | F17: 0 | G17: 1249 | H17: =SUM(F17+G17) -> 1249 | I17: =F17*55000*0.35/1000/0.55 -> 0 | J17: =G17*55000*0.35/1000/0.55 -> 43715 | K17: =J17+I17 -> 43715 | L17: 0 | M17: 22880 | N17: =SUM(L17+M17) -> 22880 | O17: 0 | P17: 3426.6187 | Q17: =SUM(O17+P17) -> 3426.6187 | R17: =L17-O17 -> 0 | S17: =M17-P17 -> 19453.381 | T17: =SUM(R17+S17) -> 19453.381 | U17: =R17*0.55 -> 0 | V17: =S17*0.55 -> 10699.36 | W17: =SUM(U17+V17) -> 10699.36 | X17: =U17/0.95 -> 0 | Y17: =V17/0.95 -> 11262.484 | Z17: =SUM(X17+Y17) -> 11262.484 | AA17: 0 | AB17: 10871.785 | AC17: =SUM(AA17+AB17) -> 10871.785 | AD17: =AA17*0.95 -> 0 | AE17: =AB17*0.95 -> 10328.196 | AF17: =SUM(AD17+AE17) -> 10328.196 | AG17: 0 | AH17: 395 | AI17: =SUM(AG17+AH17) -> 395 | AJ17: =AG17/1.05506 -> 0 | AK17: =AH17/1.05506 -> 374.38629 | AL17: =SUM(AJ17+AK17) -> 374.38629
B18: 45542 | E18: =SUM(C18+D18) -> 0 | F18: 0 | G18: 1072 | H18: =SUM(F18+G18) -> 1072 | I18: =F18*55000*0.35/1000/0.55 -> 0 | J18: =G18*55000*0.35/1000/0.55 -> 37520 | K18: =J18+I18 -> 37520 | L18: 0 | M18: 22649 | N18: =SUM(L18+M18) -> 22649 | O18: 0 | P18: 3582.0144 | Q18: =SUM(O18+P18) -> 3582.0144 | R18: =L18-O18 -> 0 | S18: =M18-P18 -> 19066.986 | T18: =SUM(R18+S18) -> 19066.986 | U18: =R18*0.55 -> 0 | V18: =S18*0.55 -> 10486.842 | W18: =SUM(U18+V18) -> 10486.842 | X18: =U18/0.95 -> 0 | Y18: =V18/0.95 -> 11038.781 | Z18: =SUM(X18+Y18) -> 11038.781 | AA18: 0 | AB18: 10821.899 | AC18: =SUM(AA18+AB18) -> 10821.899 | AD18: =AA18*0.95 -> 0 | AE18: =AB18*0.95 -> 10280.804 | AF18: =SUM(AD18+AE18) -> 10280.804 | AG18: 0 | AH18: 393 | AI18: =SUM(AG18+AH18) -> 393 | AJ18: =AG18/1.05506 -> 0 | AK18: =AH18/1.05506 -> 372.49066 | AL18: =SUM(AJ18+AK18) -> 372.49066
B19: 45543 | E19: =SUM(C19+D19) -> 0 | F19: 0 | G19: 1000 | H19: =SUM(F19+G19) -> 1000 | I19: =F19*55000*0.35/1000/0.55 -> 0 | J19: =G19*55000*0.35/1000/0.55 -> 35000 | K19: =J19+I19 -> 35000 | L19: 0 | M19: 22232 | N19: =SUM(L19+M19) -> 22232 | O19: 0 | P19: 3258.9928 | Q19: =SUM(O19+P19) -> 3258.9928 | R19: =L19-O19 -> 0 | S19: =M19-P19 -> 18973.007 | T19: =SUM(R19+S19) -> 18973.007 | U19: =R19*0.55 -> 0 | V19: =S19*0.55 -> 10435.154 | W19: =SUM(U19+V19) -> 10435.154 | X19: =U19/0.95 -> 0 | Y19: =V19/0.95 -> 10984.373 | Z19: =SUM(X19+Y19) -> 10984.373 | AA19: 0 | AB19: 10900.653 | AC19: =SUM(AA19+AB19) -> 10900.653 | AD19: =AA19*0.95 -> 0 | AE19: =AB19*0.95 -> 10355.62 | AF19: =SUM(AD19+AE19) -> 10355.62 | AG19: 0 | AH19: 395 | AI19: =SUM(AG19+AH19) -> 395 | AJ19: =AG19/1.05506 -> 0 | AK19: =AH19/1.05506 -> 374.38629 | AL19: =SUM(AJ19+AK19) -> 374.38629
B20: 45544 | E20: =SUM(C20+D20) -> 0 | F20: 0 | G20: 799 | H20: =SUM(F20+G20) -> 799 | I20: =F20*55000*0.35/1000/0.55 -> 0 | J20: =G20*55000*0.35/1000/0.55 -> 27965 | K20: =J20+I20 -> 27965 | L20: 0 | M20: 22158 | N20: =SUM(L20+M20) -> 22158 | O20: 0 | P20: 3534.1727 | Q20: =SUM(O20+P20) -> 3534.1727 | R20: =L20-O20 -> 0 | S20: =M20-P20 -> 18623.827 | T20: =SUM(R20+S20) -> 18623.827 | U20: =R20*0.55 -> 0 | V20: =S20*0.55 -> 10243.105 | W20: =SUM(U20+V20) -> 10243.105 | X20: =U20/0.95 -> 0 | Y20: =V20/0.95 -> 10782.216 | Z20: =SUM(X20+Y20) -> 10782.216 | AA20: 0 | AB20: 10872.797 | AC20: =SUM(AA20+AB20) -> 10872.797 | AD20: =AA20*0.95 -> 0 | AE20: =AB20*0.95 -> 10329.158 | AF20: =SUM(AD20+AE20) -> 10329.158 | AG20: 0 | AH20: 394 | AI20: =SUM(AG20+AH20) -> 394 | AJ20: =AG20/1.05506 -> 0 | AK20: =AH20/1.05506 -> 373.43848 | AL20: =SUM(AJ20+AK20) -> 373.43848
B21: 45545 | E21: =SUM(C21+D21) -> 0 | F21: 0 | G21: 1401 | H21: =SUM(F21+G21) -> 1401 | I21: =F21*55000*0.35/1000/0.55 -> 0 | J21: =G21*55000*0.35/1000/0.55 -> 49035 | K21: =J21+I21 -> 49035 | L21: 0 | M21: 21975 | N21: =SUM(L21+M21) -> 21975 | O21: 0 | P21: 3721.5827 | Q21: =SUM(O21+P21) -> 3721.5827 | R21: =L21-O21 -> 0 | S21: =M21-P21 -> 18253.417 | T21: =SUM(R21+S21) -> 18253.417 | U21: =R21*0.55 -> 0 | V21: =S21*0.55 -> 10039.379 | W21: =SUM(U21+V21) -> 10039.379 | X21: =U21/0.95 -> 0 | Y21: =V21/0.95 -> 10567.768 | Z21: =SUM(X21+Y21) -> 10567.768 | AA21: 0 | AB21: 10847.049 | AC21: =SUM(AA21+AB21) -> 10847.049 | AD21: =AA21*0.95 -> 0 | AE21: =AB21*0.95 -> 10304.696 | AF21: =SUM(AD21+AE21) -> 10304.696 | AG21: 0 | AH21: 393 | AI21: =SUM(AG21+AH21) -> 393 | AJ21: =AG21/1.05506 -> 0 | AK21: =AH21/1.05506 -> 372.49066 | AL21: =SUM(AJ21+AK21) -> 372.49066
B22: 45546 | E22: =SUM(C22+D22) -> 0 | F22: 0 | G22: 1273 | H22: =SUM(F22+G22) -> 1273 | I22: =F22*55000*0.35/1000/0.55 -> 0 | J22: =G22*55000*0.35/1000/0.55 -> 44555 | K22: =J22+I22 -> 44555 | L22: 0 | M22: 22004 | N22: =SUM(L22+M22) -> 22004 | O22: 0 | P22: 3577.6978 | Q22: =SUM(O22+P22) -> 3577.6978 | R22: =L22-O22 -> 0 | S22: =M22-P22 -> 18426.302 | T22: =SUM(R22+S22) -> 18426.302 | U22: =R22*0.55 -> 0 | V22: =S22*0.55 -> 10134.466 | W22: =SUM(U22+V22) -> 10134.466 | X22: =U22/0.95 -> 0 | Y22: =V22/0.95 -> 10667.859 | Z22: =SUM(X22+Y22) -> 10667.859 | AA22: 0 | AB22: 10163.378 | AC22: =SUM(AA22+AB22) -> 10163.378 | AD22: =AA22*0.95 -> 0 | AE22: =AB22*0.95 -> 9655.2087 | AF22: =SUM(AD22+AE22) -> 9655.2087 | AG22: 0 | AH22: 368 | AI22: =SUM(AG22+AH22) -> 368 | AJ22: =AG22/1.05506 -> 0 | AK22: =AH22/1.05506 -> 348.79533 | AL22: =SUM(AJ22+AK22) -> 348.79533
B23: 45547 | E23: =SUM(C23+D23) -> 0 | F23: 0 | G23: 1231 | H23: =SUM(F23+G23) -> 1231 | I23: =F23*55000*0.35/1000/0.55 -> 0 | J23: =G23*55000*0.35/1000/0.55 -> 43085 | K23: =J23+I23 -> 43085 | L23: 0 | M23: 18773 | N23: =SUM(L23+M23) -> 18773 | O23: 0 | P23: 2806.4748 | Q23: =SUM(O23+P23) -> 2806.4748 | R23: =L23-O23 -> 0 | S23: =M23-P23 -> 15966.525 | T23: =SUM(R23+S23) -> 15966.525 | U23: =R23*0.55 -> 0 | V23: =S23*0.55 -> 8781.5888 | W23: =SUM(U23+V23) -> 8781.5888 | X23: =U23/0.95 -> 0 | Y23: =V23/0.95 -> 9243.7777 | Z23: =SUM(X23+Y23) -> 9243.7777 | AA23: 0 | AB23: 6777.8004 | AC23: =SUM(AA23+AB23) -> 6777.8004 | AD23: =AA23*0.95 -> 0 | AE23: =AB23*0.95 -> 6438.9104 | AF23: =SUM(AD23+AE23) -> 6438.9104 | AG23: 0 | AH23: 246 | AI23: =SUM(AG23+AH23) -> 246 | AJ23: =AG23/1.05506 -> 0 | AK23: =AH23/1.05506 -> 233.16209 | AL23: =SUM(AJ23+AK23) -> 233.16209
... B40: 45564 | E40: =SUM(C40+D40) -> 0 | F40: 496 | G40: 0 | H40: =SUM(F40+G40) -> 496 | I40: =F40*55000*0.35/1000/0.55 -> 17360 | J40: =G40*55000*0.35/1000/0.55 -> 0 | K40: =J40+I40 -> 17360 | L40: 20801 | M40: 0 | N40: =SUM(L40+M40) -> 20801 | O40: 3861.5108 | P40: 0 | Q40: =SUM(O40+P40) -> 3861.5108 | R40: =L40-O40 -> 16939.489 | S40: =M40-P40 -> 0 | T40: =SUM(R40+S40) -> 16939.489 | U40: =R40*0.55 -> 9316.7191 | V40: =S40*0.55 -> 0 | W40: =SUM(U40+V40) -> 9316.7191 | X40: =U40/0.95 -> 9807.0727 | Y40: =V40/0.95 -> 0 | Z40: =SUM(X40+Y40) -> 9807.0727 | AA40: 10078.4 | AB40: 0 | AC40: =SUM(AA40+AB40) -> 10078.4 | AD40: =AA40*0.95 -> 9574.4799 | AE40: =AB40*0.95 -> 0 | AF40: =SUM(AD40+AE40) -> 9574.4799 | AG40: 358 | AH40: 0 | AI40: =SUM(AG40+AH40) -> 358 | AJ40: =AG40/1.05506 -> 339.3172 | AK40: =AH40/1.05506 -> 0 | AL40: =SUM(AJ40+AK40) -> 339.3172
B41: 45565 | E41: =SUM(C41+D41) -> 0 | F41: 1224 | G41: 0 | H41: =SUM(F41+G41) -> 1224 | I41: =F40*55000*0.35/1000/0.55 -> 17360 | J41: =G40*55000*0.35/1000/0.55 -> 0 | K41: =J41+I41 -> 17360 | L41: 17559 | M41: 0 | N41: =SUM(L41+M41) -> 17559 | O41: 2923.3813 | P41: 0 | Q41: =SUM(O41+P41) -> 2923.3813 | R41: =L41-O41 -> 14635.619 | S41: =M41-P41 -> 0 | T41: =SUM(R41+S41) -> 14635.619 | U41: =R41*0.55 -> 8049.5903 | V41: =S41*0.55 -> 0 | W41: =SUM(U41+V41) -> 8049.5903 | X41: =U41/0.95 -> 8473.2529 | Y41: =V41/0.95 -> 0 | Z41: =SUM(X41+Y41) -> 8473.2529 | AA41: 3956.2637 | AB41: 0 | AC41: =SUM(AA41+AB41) -> 3956.2637 | AD41: =AA41*0.95 -> 3758.4505 | AE41: =AB41*0.95 -> 0 | AF41: =SUM(AD41+AE41) -> 3758.4505 | AG41: 141 | AH41: 0 | AI41: =SUM(AG41+AH41) -> 141 | AJ41: =AG41/1.05506 -> 133.64169 | AK41: =AH41/1.05506 -> 0 | AL41: =SUM(AJ41+AK41) -> 133.64169
B42: Total | F42: =SUM(F12:F41) -> 9010 | G42: =SUM(G12:G41) -> 25023 | H42: =SUM(H12:H41) -> 34033 | I42: =SUM(I12:I41) -> 289870 | J42: =SUM(J12:J41) -> 875805 | K42: =SUM(K12:K41) -> 1165675 | L42: =SUM(L12:L41) -> 152727 | M42: =SUM(M12:M41) -> 509984 | ... AI42: =SUM(AI12:AI41) -> 10927 | AJ42: 2276 | AK42: =SUM(AK12:AK41) -> 8081.057 | AL42: =SUM(AL12:AL41) -> 10356.757

Sheet Oct24
A1: \
B2: Kian Hoe Plantations Berhad (KHPB) | AJ2: GJ to MMBtu
B3: MASS BALANCE (MB) WORKSHEET | AJ3: Conversion Factor | AL3: 1.05506
B4: Year: 2024
B5: DATE | C5: Opening Stock of Biogas (m3) | F5: Incoming POME to Digester (m3) | I5: Biogas Generated (m3) | L5: Biogas Supplied to Scrubber (m3) | O5: Biogas Supplied to Gas Engine (m3) | R5: Biogas Supplied to Biomethane Plant (m3) | U5: Volume CH4 in Raw Biogas (m3) | X5: Biomethane generated (m3) | AA5: Biomethane Supplied to Grid (Sm3) | AD5: Biomethane Supplied to Grid (m3) | AG5: Biomethane Supplied to Grid (GJ) | AJ5: Biomethane Supplied to Grid (MMBtu)
C10: ISCC | D10: NON-ISCC | E10: TOTAL | F10: ISCC | G10: NON-ISCC | H10: TOTAL | I10: ISCC | J10: NON-ISCC | K10: TOTAL | L10: ISCC | M10: NON-ISCC | N10: TOTAL | O10: ISCC | P10: NON-ISCC | Q10: TOTAL | R10: ISCC | S10: NON-ISCC | T10: TOTAL | U10: ISCC | V10: NON-ISCC | W10: TOTAL | X10: ISCC | Y10: NON-ISCC | Z10: TOTAL | AA10: ISCC | AB10: NON-ISCC | AC10: TOTAL | AD10: ISCC | AE10: NON-ISCC | AF10: TOTAL | AG10: ISCC | AH10: NON-ISCC | AI10: TOTAL | AJ10: ISCC | AK10: NON-ISCC | AL10: TOTAL
B11: 45565 | C11: 0 | D11: 45868 | E11: =SUM(C11+D11) -> 45868 | N11: =SUM(L11+M11) -> 0 | Q11: =SUM(O11+P11) -> 0 | T11: =SUM(R11+S11) -> 0 | W11: =SUM(U11+V11) -> 0 | Z11: =SUM(X11+Y11) -> 0 | AC11: =SUM(AA11+AB11) -> 0 | AF11: =SUM(AD11+AE11) -> 0 | AI11: =SUM(AG11+AH11) -> 0 | AL11: =SUM(AJ11+AK11) -> 0
B12: 45566 | E12: =SUM(C12+D12) -> 0 | F12: 1677 | G12: 0 | H12: =SUM(F12+G12) -> 1677 | I12: =F12*55000*0.35/1000/0.55 -> 58695 | J12: =G12*55000*0.35/1000/0.55 -> 0 | K12: =J12+I12 -> 58695 | L12: 3024 | M12: 0 | N12: =SUM(L12+M12) -> 3024 | O12: 0 | P12: 0 | Q12: =SUM(O12+P12) -> 0 | R12: 0 | S12: =M12-P12 -> 0 | T12: =SUM(R12+S12) -> 0 | U12: =R12*0.55 -> 0 | V12: =S12*0.55 -> 0 | W12: =SUM(U12+V12) -> 0 | X12: =U12/0.95 -> 0 | Y12: =V12/0.95 -> 0 | Z12: =SUM(X12+Y12) -> 0 | AA12: 0 | AB12: 0 | AC12: =SUM(AA12+AB12) -> 0 | AD12: =AA12*0.95 -> 0 | AE12: =AB12*0.95 -> 0 | AF12: =SUM(AD12+AE12) -> 0 | AG12: 0 | AH12: 0 | AI12: =SUM(AG12+AH12) -> 0 | AJ12: =AG12/1.05506 -> 0 | AK12: =AH12/1.05506 -> 0 | AL12: =SUM(AJ12+AK12) -> 0
B13: 45567 | E13: =SUM(C13+D13) -> 0 | F13: 852 | G13: 0 | H13: =SUM(F13+G13) -> 852 | I13: =F13*55000*0.35/1000/0.55 -> 29820 | J13: =G13*55000*0.35/1000/0.55 -> 0 | K13: =J13+I13 -> 29820 | L13: 1751 | M13: 0 | N13: =SUM(L13+M13) -> 1751 | O13: 0 | P13: 0 | Q13: =SUM(O13+P13) -> 0 | R13: 0 | S13: =M13-P13 -> 0 | T13: =SUM(R13+S13) -> 0 | U13: =R13*0.55 -> 0 | V13: =S13*0.55 -> 0 | W13: =SUM(U13+V13) -> 0 | X13: =U13/0.95 -> 0 | Y13: =V13/0.95 -> 0 | Z13: =SUM(X13+Y13) -> 0 | AA13: 0 | AB13: 0 | AC13: =SUM(AA13+AB13) -> 0 | AD13: =AA13*0.95 -> 0 | AE13: =AB13*0.95 -> 0 | AF13: =SUM(AD13+AE13) -> 0 | AG13: 0 | AH13: 0 | AI13: =SUM(AG13+AH13) -> 0 | AJ13: =AG13/1.05506 -> 0 | AK13: =AH13/1.05506 -> 0 | AL13: =SUM(AJ13+AK13) -> 0
B14: 45568 | E14: =SUM(C14+D14) -> 0 | F14: 1302 | G14: 0 | H14: =SUM(F14+G14) -> 1302 | I14: =F14*55000*0.35/1000/0.55 -> 45570 | J14: =G14*55000*0.35/1000/0.55 -> 0 | K14: =J14+I14 -> 45570 | L14: 1745 | M14: 0 | N14: =SUM(L14+M14) -> 1745 | O14: 0 | P14: 0 | Q14: =SUM(O14+P14) -> 0 | R14: 0 | S14: =M14-P14 -> 0 | T14: =SUM(R14+S14) -> 0 | U14: =R14*0.55 -> 0 | V14: =S14*0.55 -> 0 | W14: =SUM(U14+V14) -> 0 | X14: =U14/0.95 -> 0 | Y14: =V14/0.95 -> 0 | Z14: =SUM(X14+Y14) -> 0 | AA14: 0 | AB14: 0 | AC14: =SUM(AA14+AB14) -> 0 | AD14: =AA14*0.95 -> 0 | AE14: =AB14*0.95 -> 0 | AF14: =SUM(AD14+AE14) -> 0 | AG14: 0 | AH14: 0 | AI14: =SUM(AG14+AH14) -> 0 | AJ14: =AG14/1.05506 -> 0 | AK14: =AH14/1.05506 -> 0 | AL14: =SUM(AJ14+AK14) -> 0
B15: 45569 | E15: =SUM(C15+D15) -> 0 | F15: 1318 | G15: 0 | H15: =SUM(F15+G15) -> 1318 | I15: =F15*55000*0.35/1000/0.55 -> 46130 | J15: =G15*55000*0.35/1000/0.55 -> 0 | K15: =J15+I15 -> 46130 | L15: 2060 | M15: 0 | N15: =SUM(L15+M15) -> 2060 | O15: 0 | P15: 0 | Q15: =SUM(O15+P15) -> 0 | R15: 0 | S15: =M15-P15 -> 0 | T15: =SUM(R15+S15) -> 0 | U15: =R15*0.55 -> 0 | V15: =S15*0.55 -> 0 | W15: =SUM(U15+V15) -> 0 | X15: =U15/0.95 -> 0 | Y15: =V15/0.95 -> 0 | Z15: =SUM(X15+Y15) -> 0 | AA15: 0 | AB15: 0 | AC15: =SUM(AA15+AB15) -> 0 | AD15: =AA15*0.95 -> 0 | AE15: =AB15*0.95 -> 0 | AF15: =SUM(AD15+AE15) -> 0 | AG15: 0 | AH15: 0 | AI15: =SUM(AG15+AH15) -> 0 | AJ15: =AG15/1.05506 -> 0 | AK15: =AH15/1.05506 -> 0 | AL15: =SUM(AJ15+AK15) -> 0
B16: 45570 | E16: =SUM(C16+D16) -> 0 | F16: 1268 | G16: 0 | H16: =SUM(F16+G16) -> 1268 | I16: =F16*55000*0.35/1000/0.55 -> 44380 | J16: =G16*55000*0.35/1000/0.55 -> 0 | K16: =J16+I16 -> 44380 | L16: 2587 | M16: 0 | N16: =SUM(L16+M16) -> 2587 | O16: 0 | P16: 0 | Q16: =SUM(O16+P16) -> 0 | R16: 0 | S16: =M16-P16 -> 0 | T16: =SUM(R16+S16) -> 0 | U16: =R16*0.55 -> 0 | V16: =S16*0.55 -> 0 | W16: =SUM(U16+V16) -> 0 | X16: =U16/0.95 -> 0 | Y16: =V16/0.95 -> 0 | Z16: =SUM(X16+Y16) -> 0 | AA16: 0 | AB16: 0 | AC16: =SUM(AA16+AB16) -> 0 | AD16: =AA16*0.95 -> 0 | AE16: =AB16*0.95 -> 0 | AF16: =SUM(AD16+AE16) -> 0 | AG16: 0 | AH16: 0 | AI16: =SUM(AG16+AH16) -> 0 | AJ16: =AG16/1.05506 -> 0 | AK16: =AH16/1.05506 -> 0 | AL16: =SUM(AJ16+AK16) -> 0
B17: 45571 | E17: =SUM(C17+D17) -> 0 | F17: 520 | G17: 0 | H17: =SUM(F17+G17) -> 520 | I17: =F17*55000*0.35/1000/0.55 -> 18200 | J17: =G17*55000*0.35/1000/0.55 -> 0 | K17: =J17+I17 -> 18200 | L17: 3218 | M17: 0 | N17: =SUM(L17+M17) -> 3218 | O17: 0 | P17: 0 | Q17: =SUM(O17+P17) -> 0 | R17: 0 | S17: =M17-P17 -> 0 | T17: =SUM(R17+S17) -> 0 | U17: =R17*0.55 -> 0 | V17: =S17*0.55 -> 0 | W17: =SUM(U17+V17) -> 0 | X17: =U17/0.95 -> 0 | Y17: =V17/0.95 -> 0 | Z17: =SUM(X17+Y17) -> 0 | AA17: 0 | AB17: 0 | AC17: =SUM(AA17+AB17) -> 0 | AD17: =AA17*0.95 -> 0 | AE17: =AB17*0.95 -> 0 | AF17: =SUM(AD17+AE17) -> 0 | AG17: 0 | AH17: 0 | AI17: =SUM(AG17+AH17) -> 0 | AJ17: =AG17/1.05506 -> 0 | AK17: =AH17/1.05506 -> 0 | AL17: =SUM(AJ17+AK17) -> 0
B18: 45572 | E18: =SUM(C18+D18) -> 0 | F18: 969 | G18: 0 | H18: =SUM(F18+G18) -> 969 | I18: =F18*55000*0.35/1000/0.55 -> 33915 | J18: =G18*55000*0.35/1000/0.55 -> 0 | K18: =J18+I18 -> 33915 | L18: 2908 | M18: 0 | N18: =SUM(L18+M18) -> 2908 | O18: 0 | P18: 0 | Q18: =SUM(O18+P18) -> 0 | R18: 0 | S18: =M18-P18 -> 0 | T18: =SUM(R18+S18) -> 0 | U18: =R18*0.55 -> 0 | V18: =S18*0.55 -> 0 | W18: =SUM(U18+V18) -> 0 | X18: =U18/0.95 -> 0 | Y18: =V18/0.95 -> 0 | Z18: =SUM(X18+Y18) -> 0 | AA18: 0 | AB18: 0 | AC18: =SUM(AA18+AB18) -> 0 | AD18: =AA18*0.95 -> 0 | AE18: =AB18*0.95 -> 0 | AF18: =SUM(AD18+AE18) -> 0 | AG18: 0 | AH18: 0 | AI18: =SUM(AG18+AH18) -> 0 | AJ18: =AG18/1.05506 -> 0 | AK18: =AH18/1.05506 -> 0 | AL18: =SUM(AJ18+AK18) -> 0
B19: 45573 | E19: =SUM(C19+D19) -> 0 | F19: 1297 | G19: 0 | H19: =SUM(F19+G19) -> 1297 | I19: =F19*55000*0.35/1000/0.55 -> 45395 | J19: =G19*55000*0.35/1000/0.55 -> 0 | K19: =J19+I19 -> 45395 | L19: 4982 | M19: 0 | N19: =SUM(L19+M19) -> 4982 | O19: 0 | P19: 0 | Q19: =SUM(O19+P19) -> 0 | R19: 0 | S19: =M19-P19 -> 0 | T19: =SUM(R19+S19) -> 0 | U19: =R19*0.55 -> 0 | V19: =S19*0.55 -> 0 | W19: =SUM(U19+V19) -> 0 | X19: =U19/0.95 -> 0 | Y19: =V19/0.95 -> 0 | Z19: =SUM(X19+Y19) -> 0 | AA19: 0 | AB19: 0 | AC19: =SUM(AA19+AB19) -> 0 | AD19: =AA19*0.95 -> 0 | AE19: =AB19*0.95 -> 0 | AF19: =SUM(AD19+AE19) -> 0 | AG19: 0 | AH19: 0 | AI19: =SUM(AG19+AH19) -> 0 | AJ19: =AG19/1.05506 -> 0 | AK19: =AH19/1.05506 -> 0 | AL19: =SUM(AJ19+AK19) -> 0
B20: 45574 | E20: =SUM(C20+D20) -> 0 | F20: 1402 | G20: 0 | H20: =SUM(F20+G20) -> 1402 | I20: =F20*55000*0.35/1000/0.55 -> 49070 | J20: =G20*55000*0.35/1000/0.55 -> 0 | K20: =J20+I20 -> 49070 | L20: 6094 | M20: 0 | N20: =SUM(L20+M20) -> 6094 | O20: 0 | P20: 0 | Q20: =SUM(O20+P20) -> 0 | R20: 0 | S20: =M20-P20 -> 0 | T20: =SUM(R20+S20) -> 0 | U20: =R20*0.55 -> 0 | V20: =S20*0.55 -> 0 | W20: =SUM(U20+V20) -> 0 | X20: =U20/0.95 -> 0 | Y20: =V20/0.95 -> 0 | Z20: =SUM(X20+Y20) -> 0 | AA20: 0 | AB20: 0 | AC20: =SUM(AA20+AB20) -> 0 | AD20: =AA20*0.95 -> 0 | AE20: =AB20*0.95 -> 0 | AF20: =SUM(AD20+AE20) -> 0 | AG20: 0 | AH20: 0 | AI20: =SUM(AG20+AH20) -> 0 | AJ20: =AG20/1.05506 -> 0 | AK20: =AH20/1.05506 -> 0 | AL20: =SUM(AJ20+AK20) -> 0
B21: 45575 | E21: =SUM(C21+D21) -> 0 | F21: 1273 | G21: 0 | H21: =SUM(F21+G21) -> 1273 | I21: =F21*55000*0.35/1000/0.55 -> 44555 | J21: =G21*55000*0.35/1000/0.55 -> 0 | K21: =J21+I21 -> 44555 | L21: 10846 | M21: 0 | N21: =SUM(L21+M21) -> 10846 | O21: 0 | P21: 0 | Q21: =SUM(O21+P21) -> 0 | R21: 0 | S21: =M21-P21 -> 0 | T21: =SUM(R21+S21) -> 0 | U21: =R21*0.55 -> 0 | V21: =S21*0.55 -> 0 | W21: =SUM(U21+V21) -> 0 | X21: =U21/0.95 -> 0 | Y21: =V21/0.95 -> 0 | Z21: =SUM(X21+Y21) -> 0 | AA21: 0 | AB21: 0 | AC21: =SUM(AA21+AB21) -> 0 | AD21: =AA21*0.95 -> 0 | AE21: =AB21*0.95 -> 0 | AF21: =SUM(AD21+AE21) -> 0 | AG21: 0 | AH21: 0 | AI21: =SUM(AG21+AH21) -> 0 | AJ21: =AG21/1.05506 -> 0 | AK21: =AH21/1.05506 -> 0 | AL21: =SUM(AJ21+AK21) -> 0
B22: 45576 | E22: =SUM(C22+D22) -> 0 | F22: 1258 | G22: 0 | H22: =SUM(F22+G22) -> 1258 | I22: =F22*55000*0.35/1000/0.55 -> 44030 | J22: =G22*55000*0.35/1000/0.55 -> 0 | K22: =J22+I22 -> 44030 | L22: 14861 | M22: 0 | N22: =SUM(L22+M22) -> 14861 | O22: 0 | P22: 0 | Q22: =SUM(O22+P22) -> 0 | R22: 0 | S22: =M22-P22 -> 0 | T22: =SUM(R22+S22) -> 0 | U22: =R22*0.55 -> 0 | V22: =S22*0.55 -> 0 | W22: =SUM(U22+V22) -> 0 | X22: =U22/0.95 -> 0 | Y22: =V22/0.95 -> 0 | Z22: =SUM(X22+Y22) -> 0 | AA22: 0 | AB22: 0 | AC22: =SUM(AA22+AB22) -> 0 | AD22: =AA22*0.95 -> 0 | AE22: =AB22*0.95 -> 0 | AF22: =SUM(AD22+AE22) -> 0 | AG22: 0 | AH22: 0 | AI22: =SUM(AG22+AH22) -> 0 | AJ22: =AG22/1.05506 -> 0 | AK22: =AH22/1.05506 -> 0 | AL22: =SUM(AJ22+AK22) -> 0
B23: 45577 | E23: =SUM(C23+D23) -> 0 | F23: 1205 | G23: 0 | H23: =SUM(F23+G23) -> 1205 | I23: =F23*55000*0.35/1000/0.55 -> 42175 | J23: =G23*55000*0.35/1000/0.55 -> 0 | K23: =J23+I23 -> 42175 | L23: 19540 | M23: 0 | N23: =SUM(L23+M23) -> 19540 | O23: 0 | P23: 0 | Q23: =SUM(O23+P23) -> 0 | R23: 0 | S23: =M23-P23 -> 0 | T23: =SUM(R23+S23) -> 0 | U23: =R23*0.55 -> 0 | V23: =S23*0.55 -> 0 | W23: =SUM(U23+V23) -> 0 | X23: =U23/0.95 -> 0 | Y23: =V23/0.95 -> 0 | Z23: =SUM(X23+Y23) -> 0 | AA23: 0 | AB23: 0 | AC23: =SUM(AA23+AB23) -> 0 | AD23: =AA23*0.95 -> 0 | AE23: =AB23*0.95 -> 0 | AF23: =SUM(AD23+AE23) -> 0 | AG23: 0 | AH23: 0 | AI23: =SUM(AG23+AH23) -> 0 | AJ23: =AG23/1.05506 -> 0 | AK23: =AH23/1.05506 -> 0 | AL23: =SUM(AJ23+AK23) -> 0
... B26: 45580 | E26: =SUM(C26+D26) -> 0 | F26: 1207 | G26: 0 | H26: =SUM(F26+G26) -> 1207 | I26: =F26*55000*0.35/1000/0.55 -> 42245 | J26: =G26*55000*0.35/1000/0.55 -> 0 | K26: =J26+I26 -> 42245 | L26: 20539 | M26: 0 | N26: =SUM(L26+M26) -> 20539 | O26: 0 | P26: 0 | Q26: =SUM(O26+P26) -> 0 | R26: 0 | S26: =M26-P26 -> 0 | T26: =SUM(R26+S26) -> 0 | U26: =R26*0.55 -> 0 | V26: =S26*0.55 -> 0 | W26: =SUM(U26+V26) -> 0 | X26: =U26/0.95 -> 0 | Y26: =V26/0.95 -> 0 | Z26: =SUM(X26+Y26) -> 0 | AA26: 0 | AB26: 0 | AC26: =SUM(AA26+AB26) -> 0 | AD26: =AA26*0.95 -> 0 | AE26: =AB26*0.95 -> 0 | AF26: =SUM(AD26+AE26) -> 0 | AG26: 0 | AH26: 0 | AI26: =SUM(AG26+AH26) -> 0 | AJ26: =AG26/1.05506 -> 0 | AK26: =AH26/1.05506 -> 0 | AL26: =SUM(AJ26+AK26) -> 0
B27: 45581 | E27: =SUM(C27+D27) -> 0 | F27: 1155 | G27: 0 | H27: =SUM(F27+G27) -> 1155 | I27: =F27*55000*0.35/1000/0.55 -> 40425 | J27: =G27*55000*0.35/1000/0.55 -> 0 | K27: =J27+I27 -> 40425 | L27: 23073 | M27: 0 | N27: =SUM(L27+M27) -> 23073 | O27: 618.70504 | P27: 0 | Q27: =SUM(O27+P27) -> 618.70504 | R27: =L27-O27 -> 22454.295 | S27: =M27-P27 -> 0 | T27: =SUM(R27+S27) -> 22454.295 | U27: =R27*0.55 -> 12349.862 | V27: =S27*0.55 -> 0 | W27: =SUM(U27+V27) -> 12349.862 | X27: =U27/0.95 -> 12999.855 | Y27: =V27/0.95 -> 0 | Z27: =SUM(X27+Y27) -> 12999.855 | AA27: 0 | AB27: 0 | AC27: =SUM(AA27+AB27) -> 0 | AD27: =AA27*0.95 -> 0 | AE27: =AB27*0.95 -> 0 | AF27: =SUM(AD27+AE27) -> 0 | AG27: 0 | AH27: 0 | AI27: =SUM(AG27+AH27) -> 0 | AJ27: =AG27/1.05506 -> 0 | AK27: =AH27/1.05506 -> 0 | AL27: =SUM(AJ27+AK27) -> 0
B28: 45582 | E28: =SUM(C28+D28) -> 0 | F28: 1097 | G28: 0 | H28: =SUM(F28+G28) -> 1097 | I28: =F28*55000*0.35/1000/0.55 -> 38395 | J28: =G28*55000*0.35/1000/0.55 -> 0 | K28: =J28+I28 -> 38395 | L28: 23706 | M28: 0 | N28: =SUM(L28+M28) -> 23706 | O28: 2008.6331 | P28: 0 | Q28: =SUM(O28+P28) -> 2008.6331 | R28: =L28-O28 -> 21697.367 | S28: =M28-P28 -> 0 | T28: =SUM(R28+S28) -> 21697.367 | U28: =R28*0.55 -> 11933.552 | V28: =S28*0.55 -> 0 | W28: =SUM(U28+V28) -> 11933.552 | X28: =U28/0.95 -> 12561.633 | Y28: =V28/0.95 -> 0 | Z28: =SUM(X28+Y28) -> 12561.633 | AA28: 0 | AB28: 0 | AC28: =SUM(AA28+AB28) -> 0 | AD28: =AA28*0.95 -> 0 | AE28: =AB28*0.95 -> 0 | AF28: =SUM(AD28+AE28) -> 0 | AG28: 0 | AH28: 0 | AI28: =SUM(AG28+AH28) -> 0 | AJ28: =AG28/1.05506 -> 0 | AK28: =AH28/1.05506 -> 0 | AL28: =SUM(AJ28+AK28) -> 0
B29: 45583 | E29: =SUM(C29+D29) -> 0 | F29: 867 | G29: 0 | H29: =SUM(F29+G29) -> 867 | I29: =F29*55000*0.35/1000/0.55 -> 30345 | J29: =G29*55000*0.35/1000/0.55 -> 0 | K29: =J29+I29 -> 30345 | L29: 28007 | M29: 0 | N29: =SUM(L29+M29) -> 28007 | O29: 3617.9856 | P29: 0 | Q29: =SUM(O29+P29) -> 3617.9856 | R29: =L29-O29 -> 24389.014 | S29: =M29-P29 -> 0 | T29: =SUM(R29+S29) -> 24389.014 | U29: =R29*0.55 -> 13413.958 | V29: =S29*0.55 -> 0 | W29: =SUM(U29+V29) -> 13413.958 | X29: =U29/0.95 -> 14119.956 | Y29: =V29/0.95 -> 0 | Z29: =SUM(X29+Y29) -> 14119.956 | AA29: 6193.002 | AB29: 0 | AC29: =SUM(AA29+AB29) -> 6193.002 | AD29: =AA29*0.95 -> 5883.3519 | AE29: =AB29*0.95 -> 0 | AF29: =SUM(AD29+AE29) -> 5883.3519 | AG29: 221 | AH29: 0 | AI29: =SUM(AG29+AH29) -> 221 | AJ29: =AG29/1.05506 -> 209.46676 | AK29: =AH29/1.05506 -> 0 | AL29: =SUM(AJ29+AK29) -> 209.46676
B30: 45584 | E30: =SUM(C30+D30) -> 0 | F30: 1219 | G30: 0 | H30: =SUM(F30+G30) -> 1219 | I30: =F30*55000*0.35/1000/0.55 -> 42665 | J30: =G30*55000*0.35/1000/0.55 -> 0 | K30: =J30+I30 -> 42665 | L30: 29774 | M30: 0 | N30: =SUM(L30+M30) -> 29774 | O30: 4299.2806 | P30: 0 | Q30: =SUM(O30+P30) -> 4299.2806 | R30: =L30-O30 -> 25474.719 | S30: =M30-P30 -> 0 | T30: =SUM(R30+S30) -> 25474.719 | U30: =R30*0.55 -> 14011.096 | V30: =S30*0.55 -> 0 | W30: =SUM(U30+V30) -> 14011.096 | X30: =U30/0.95 -> 14748.522 | Y30: =V30/0.95 -> 0 | Z30: =SUM(X30+Y30) -> 14748.522 | AA30: 9349.1747 | AB30: 0 | AC30: =SUM(AA30+AB30) -> 9349.1747 | AD30: =AA30*0.95 -> 8881.716 | AE30: =AB30*0.95 -> 0 | AF30: =SUM(AD30+AE30) -> 8881.716 | AG30: 333 | AH30: 0 | AI30: =SUM(AG30+AH30) -> 333 | AJ30: =AG30/1.05506 -> 315.62186 | AK30: =AH30/1.05506 -> 0 | AL30: =SUM(AJ30+AK30) -> 315.62186
B31: 45585 | E31: =SUM(C31+D31) -> 0 | F31: 112 | G31: 0 | H31: =SUM(F31+G31) -> 112 | I31: =F31*55000*0.35/1000/0.55 -> 3920 | J31: =G31*55000*0.35/1000/0.55 -> 0 | K31: =J31+I31 -> 3920 | L31: 27595 | M31: 0 | N31: =SUM(L31+M31) -> 27595 | O31: 3526.259 | P31: 0 | Q31: =SUM(O31+P31) -> 3526.259 | R31: =L31-O31 -> 24068.741 | S31: =M31-P31 -> 0 | T31: =SUM(R31+S31) -> 24068.741 | U31: =R31*0.55 -> 13237.808 | V31: =S31*0.55 -> 0 | W31: =SUM(U31+V31) -> 13237.808 | X31: =U31/0.95 -> 13934.534 | Y31: =V31/0.95 -> 0 | Z31: =SUM(X31+Y31) -> 13934.534 | AA31: 9712.2522 | AB31: 0 | AC31: =SUM(AA31+AB31) -> 9712.2522 | AD31: =AA31*0.95 -> 9226.6396 | AE31: =AB31*0.95 -> 0 | AF31: =SUM(AD31+AE31) -> 9226.6396 | AG31: 350 | AH31: 0 | AI31: =SUM(AG31+AH31) -> 350 | AJ31: =AG31/1.05506 -> 331.73469 | AK31: =AH31/1.05506 -> 0 | AL31: =SUM(AJ31+AK31) -> 331.73469
B32: 45586 | E32: =SUM(C32+D32) -> 0 | F32: 1064 | G32: 0 | H32: =SUM(F32+G32) -> 1064 | I32: =F32*55000*0.35/1000/0.55 -> 37240 | J32: =G32*55000*0.35/1000/0.55 -> 0 | K32: =J32+I32 -> 37240 | L32: 27010 | M32: 0 | N32: =SUM(L32+M32) -> 27010 | O32: 3883.0935 | P32: 0 | Q32: =SUM(O32+P32) -> 3883.0935 | R32: =L32-O32 -> 23126.906 | S32: =M32-P32 -> 0 | T32: =SUM(R32+S32) -> 23126.906 | U32: =R32*0.55 -> 12719.799 | V32: =S32*0.55 -> 0 | W32: =SUM(U32+V32) -> 12719.799 | X32: =U32/0.95 -> 13389.262 | Y32: =V32/0.95 -> 0 | Z32: =SUM(X32+Y32) -> 13389.262 | AA32: 8958.2236 | AB32: 0 | AC32: =SUM(AA32+AB32) -> 8958.2236 | AD32: =AA32*0.95 -> 8510.3124 | AE32: =AB32*0.95 -> 0 | AF32: =SUM(AD32+AE32) -> 8510.3124 | AG32: 317 | AH32: 0 | AI32: =SUM(AG32+AH32) -> 317 | AJ32: =AG32/1.05506 -> 300.45685 | AK32: =AH32/1.05506 -> 0 | AL32: =SUM(AJ32+AK32) -> 300.45685
B33: 45587 | E33: =SUM(C33+D33) -> 0 | F33: 1629 | G33: 0 | H33: =SUM(F33+G33) -> 1629 | I33: =F33*55000*0.35/1000/0.55 -> 57015 | J33: =G33*55000*0.35/1000/0.55 -> 0 | K33: =J33+I33 -> 57015 | L33: 28815 | M33: 0 | N33: =SUM(L33+M33) -> 28815 | O33: 3934.8921 | P33: 0 | Q33: =SUM(O33+P33) -> 3934.8921 | R33: =L33-O33 -> 24880.108 | S33: =M33-P33 -> 0 | T33: =SUM(R33+S33) -> 24880.108 | U33: =R33*0.55 -> 13684.059 | V33: =S33*0.55 -> 0 | W33: =SUM(U33+V33) -> 13684.059 | X33: =U33/0.95 -> 14404.273 | Y33: =V33/0.95 -> 0 | Z33: =SUM(X33+Y33) -> 14404.273 | AA33: 7708.1951 | AB33: 0 | AC33: =SUM(AA33+AB33) -> 7708.1951 | AD33: =AA33*0.95 -> 7322.7853 | AE33: =AB33*0.95 -> 0 | AF33: =SUM(AD33+AE33) -> 7322.7853 | AG33: 277 | AH33: 0 | AI33: =SUM(AG33+AH33) -> 277 | AJ33: =AG33/1.05506 -> 262.54431 | AK33: =AH33/1.05506 -> 0 | AL33: =SUM(AJ33+AK33) -> 262.54431
B34: 45588 | E34: =SUM(C34+D34) -> 0 | F34: 1145 | G34: 0 | H34: =SUM(F34+G34) -> 1145 | I34: =F34*55000*0.35/1000/0.55 -> 40075 | J34: =G34*55000*0.35/1000/0.55 -> 0 | K34: =J34+I34 -> 40075 | L34: 29714 | M34: 0 | N34: =SUM(L34+M34) -> 29714 | O34: 3900 | P34: 0 | Q34: =SUM(O34+P34) -> 3900 | R34: =L34-O34 -> 25814 | S34: =M34-P34 -> 0 | T34: =SUM(R34+S34) -> 25814 | U34: =R34*0.55 -> 14197.7 | V34: =S34*0.55 -> 0 | W34: =SUM(U34+V34) -> 14197.7 | X34: =U34/0.95 -> 14944.947 | Y34: =V34/0.95 -> 0 | Z34: =SUM(X34+Y34) -> 14944.947 | AA34: 7671.35 | AB34: 0 | AC34: =SUM(AA34+AB34) -> 7671.35 | AD34: =AA34*0.95 -> 7287.7825 | AE34: =AB34*0.95 -> 0 | AF34: =SUM(AD34+AE34) -> 7287.7825 | AG34: 275 | AH34: 0 | AI34: =SUM(AG34+AH34) -> 275 | AJ34: =AG34/1.05506 -> 260.64868 | AK34: =AH34/1.05506 -> 0 | AL34: =SUM(AJ34+AK34) -> 260.64868
B35: 45589 | E35: =SUM(C35+D35) -> 0 | F35: 921 | G35: 0 | H35: =SUM(F35+G35) -> 921 | I35: =F35*55000*0.35/1000/0.55 -> 32235 | J35: =G35*55000*0.35/1000/0.55 -> 0 | K35: =J35+I35 -> 32235 | L35: 30736 | M35: 0 | N35: =SUM(L35+M35) -> 30736 | O35: 4133.8129 | P35: 0 | Q35: =SUM(O35+P35) -> 4133.8129 | R35: =L35-O35 -> 26602.187 | S35: =M35-P35 -> 0 | T35: =SUM(R35+S35) -> 26602.187 | U35: =R35*0.55 -> 14631.203 | V35: =S35*0.55 -> 0 | W35: =SUM(U35+V35) -> 14631.203 | X35: =U35/0.95 -> 15401.266 | Y35: =V35/0.95 -> 0 | Z35: =SUM(X35+Y35) -> 15401.266 | AA35: 8383.8147 | AB35: 0 | AC35: =SUM(AA35+AB35) -> 8383.8147 | AD35: =AA35*0.95 -> 7964.624 | AE35: =AB35*0.95 -> 0 | AF35: =SUM(AD35+AE35) -> 7964.624 | AG35: 300 | AH35: 0 | AI35: =SUM(AG35+AH35) -> 300 | AJ35: =AG35/1.05506 -> 284.34402 | AK35: =AH35/1.05506 -> 0 | AL35: =SUM(AJ35+AK35) -> 284.34402
B36: 45590 | E36: =SUM(C36+D36) -> 0 | F36: 828 | G36: 0 | H36: =SUM(F36+G36) -> 828 | I36: =F36*55000*0.35/1000/0.55 -> 28980 | J36: =G36*55000*0.35/1000/0.55 -> 0 | K36: =J36+I36 -> 28980 | L36: 30869 | M36: 0 | N36: =SUM(L36+M36) -> 30869 | O36: 4064.7482 | P36: 0 | Q36: =SUM(O36+P36) -> 4064.7482 | R36: =L36-O36 -> 26804.252 | S36: =M36-P36 -> 0 | T36: =SUM(R36+S36) -> 26804.252 | U36: =R36*0.55 -> 14742.338 | V36: =S36*0.55 -> 0 | W36: =SUM(U36+V36) -> 14742.338 | X36: =U36/0.95 -> 15518.251 | Y36: =V36/0.95 -> 0 | Z36: =SUM(X36+Y36) -> 15518.251 | AA36: 8612.9226 | AB36: 0 | AC36: =SUM(AA36+AB36) -> 8612.9226 | AD36: =AA36*0.95 -> 8182.2765 | AE36: =AB36*0.95 -> 0 | AF36: =SUM(AD36+AE36) -> 8182.2765 | AG36: 308 | AH36: 0 | AI36: =SUM(AG36+AH36) -> 308 | AJ36: =AG36/1.05506 -> 291.92653 | AK36: =AH36/1.05506 -> 0 | AL36: =SUM(AJ36+AK36) -> 291.92653
B37: 45591 | E37: =SUM(C37+D37) -> 0 | F37: 1069 | G37: 0 | H37: =SUM(F37+G37) -> 1069 | I37: =F37*55000*0.35/1000/0.55 -> 37415 | J37: =G37*55000*0.35/1000/0.55 -> 0 | K37: =J37+I37 -> 37415 | L37: 30915 | M37: 0 | N37: =SUM(L37+M37) -> 30915 | O37: 3749.6403 | P37: 0 | Q37: =SUM(O37+P37) -> 3749.6403 | R37: =L37-O37 -> 27165.36 | S37: =M37-P37 -> 0 | T37: =SUM(R37+S37) -> 27165.36 | U37: =R37*0.55 -> 14940.948 | V37: =S37*0.55 -> 0 | W37: =SUM(U37+V37) -> 14940.948 | X37: =U37/0.95 -> 15727.314 | Y37: =V37/0.95 -> 0 | Z37: =SUM(X37+Y37) -> 15727.314 | AA37: 8730.4264 | AB37: 0 | AC37: =SUM(AA37+AB37) -> 8730.4264 | AD37: =AA37*0.95 -> 8293.9051 | AE37: =AB37*0.95 -> 0 | AF37: =SUM(AD37+AE37) -> 8293.9051 | AG37: 312 | AH37: 0 | AI37: =SUM(AG37+AH37) -> 312 | AJ37: =AG37/1.05506 -> 295.71778 | AK37: =AH37/1.05506 -> 0 | AL37: =SUM(AJ37+AK37) -> 295.71778
B38: 45592 | E38: =SUM(C38+D38) -> 0 | F38: 0 | G38: 0 | H38: =SUM(F38+G38) -> 0 | I38: =F38*55000*0.35/1000/0.55 -> 0 | J38: =G38*55000*0.35/1000/0.55 -> 0 | K38: =J38+I38 -> 0 | L38: 31266 | M38: 0 | N38: =SUM(L38+M38) -> 31266 | O38: 3427.6978 | P38: 0 | Q38: =SUM(O38+P38) -> 3427.6978 | R38: =L38-O38 -> 27838.302 | S38: =M38-P38 -> 0 | T38: =SUM(R38+S38) -> 27838.302 | U38: =R38*0.55 -> 15311.066 | V38: =S38*0.55 -> 0 | W38: =SUM(U38+V38) -> 15311.066 | X38: =U38/0.95 -> 16116.912 | Y38: =V38/0.95 -> 0 | Z38: =SUM(X38+Y38) -> 16116.912 | AA38: 8773.3857 | AB38: 0 | AC38: =SUM(AA38+AB38) -> 8773.3857 | AD38: =AA38*0.95 -> 8334.7164 | AE38: =AB38*0.95 -> 0 | AF38: =SUM(AD38+AE38) -> 8334.7164 | AG38: 314 | AH38: 0 | AI38: =SUM(AG38+AH38) -> 314 | AJ38: =AG38/1.05506 -> 297.61341 | AK38: =AH38/1.05506 -> 0 | AL38: =SUM(AJ38+AK38) -> 297.61341
... B40: 45594 | E40: =SUM(C40+D40) -> 0 | F40: 828 | G40: 0 | H40: =SUM(F40+G40) -> 828 | I40: =F40*55000*0.35/1000/0.55 -> 28980 | J40: =G40*55000*0.35/1000/0.55 -> 0 | K40: =J40+I40 -> 28980 | L40: 29342 | M40: 0 | N40: =SUM(L40+M40) -> 29342 | O40: 3757.1942 | P40: 0 | Q40: =SUM(O40+P40) -> 3757.1942 | R40: =L40-O40 -> 25584.806 | S40: =M40-P40 -> 0 | T40: =SUM(R40+S40) -> 25584.806 | U40: =R40*0.55 -> 14071.643 | V40: =S40*0.55 -> 0 | W40: =SUM(U40+V40) -> 14071.643 | X40: =U40/0.95 -> 14812.256 | Y40: =V40/0.95 -> 0 | Z40: =SUM(X40+Y40) -> 14812.256 | AA40: 8053.7006 | AB40: 0 | AC40: =SUM(AA40+AB40) -> 8053.7006 | AD40: =AA40*0.95 -> 7651.0156 | AE40: =AB40*0.95 -> 0 | AF40: =SUM(AD40+AE40) -> 7651.0156 | AG40: 288 | AH40: 0 | AI40: =SUM(AG40+AH40) -> 288 | AJ40: =AG40/1.05506 -> 272.97026 | AK40: =AH40/1.05506 -> 0 | AL40: =SUM(AJ40+AK40) -> 272.97026
